Workbook

Sheet FPT Corp | Balance Sheet 
A1: FPT Corp | Balance Sheet 31-Jul-2024 11:26
A3: Balance Sheet
A4: Industry - Annual Standardised in Millions of Vietnamese Dong | B4: HISTORICAL
B5: 2019 | C5: 2020 | D5: 2021 | E5: 2022 | F5: 2023
A6: Earnings Quality Score | B6: 67 | C6: 93 | D6: 93 | E6: 88 | F6: 96
A7: Assets (VND Millions)
A8: Cash and Short Term Investments | B8: 10162367 | C8: 17122109 | D8: 26148566 | E8: 19487411 | F8: 24383362
A9: Cash | B9: 2611644 | C9: 2216743 | D9: 3447377 | E9: 3880860 | F9: 5975128
A10: Cash & Equivalents | B10: 841744 | C10: 2469449 | D10: 1970468 | E10: 2559317 | F10: 2304029
A11: Short Term Investments | B11: 6708978 | C11: 12435918 | D11: 20730721 | E11: 13047234 | F11: 16104205
A12: Accounts Receivable - Trade, Net | B12: 5451422 | C12: 4941737 | D12: 5681961 | E12: 7290641 | F12: 8145491
A13: Accounts Receivable - Trade, Gross | B13: 5812938 | C13: 5564392 | D13: 6211957 | E13: 7990077 | F13: 9057647
A14: Provision for Doubtful Accounts | B14: -361516 | C14: -622655 | D14: -529996 | E14: -699436 | F14: -912157
A15: Total Receivables, Net | B15: 6565329 | C15: 6119914 | D15: 6770806 | E15: 8782249 | F15: 9797658
A16: Notes Receivable - Short Term | B16: 394 | C16: 185532 | D16: 34762 | E16: 883 | F16: 515
A17: Receivables - Other | B17: 1113512 | C17: 992644 | D17: 1054084 | E17: 1490725 | F17: 1651652
A18: Total Inventory | B18: 1284201 | C18: 1290092 | D18: 1507343 | E18: 1965788 | F18: 1593411
A19: Inventories - Finished Goods | B19: 567537 | C19: 279165 | D19: 419098 | E19: 571361 | F19: 455358
... A23: Prepaid Expenses | B23: 967280 | C23: 733818 | D23: 691658 | E23: 702263 | F23: 931320
A24: Other Current Assets, Total | B24: -- | C24: -- | D24: -- | E24: -- | F24: --
A25: Total Current Assets | B25: 18979176 | C25: 25265933 | D25: 35118373 | E25: 30937711 | F25: 36705752
A26: Total Current Assets (excl. cash) | B26: =B11+B12+B18+B23 -> 14411881 | C26: =C11+C12+C18+C23 -> 19401565 | D26: =D11+D12+D18+D23 -> 28611683 | E26: =E11+E12+E18+E23 -> 23005926 | F26: =F11+F12+F18+F23 -> 26774427
A27: Property/Plant/Equipment, Total - Gross | B27: 12957590 | C27: 15324995 | D27: 17379429 | E27: 20124607 | F27: 23612265
A28: Buildings - Gross | B28: 2244612 | C28: 3160000 | D28: 5056767 | E28: 5803698 | F28: 7146778
A29: Machinery/Equipment - Gross | B29: 8316497 | C29: 9035361 | D29: 10364008 | E29: 12416314 | F29: 14327417
A30: Construction in Progress - Gross | B30: 1650471 | C30: 2373393 | D30: 1290599 | E30: 1062185 | F30: 1315270
A31: Other Property/Plant/Equipment - Gross | B31: 746010 | C31: 756241 | D31: 668056 | E31: 842411 | F31: 822799
A32: Property/Plant/Equipment, Total - Net | B32: 7948578 | C32: 9595847 | D32: 10556376 | E32: 11808040 | F32: 13701406
A33: Accumulated Depreciation, Total | B33: -5009012 | C33: -5729148 | D33: -6823053 | E33: -8316567 | F33: -9910859
A34: Goodwill, Net | B34: 225929 | C34: 200034 | D34: 465985 | E34: 407945 | F34: 1283790
A35: Goodwill - Gross | B35: -- | C35: -- | D35: -- | E35: -- | F35: --
A36: Accumulated Goodwill Amortization | B36: -- | C36: -- | D36: -- | E36: -- | F36: --
A37: Intangibles, Net | B37: 1194061 | C37: 1095369 | D37: 1133060 | E37: 1287060 | F37: 1257097
A38: Intangibles - Gross | B38: 1973814 | C38: 2036968 | D38: 2249107 | E38: 2547883 | F38: 2595587
A39: Accumulated Intangible Amortization | B39: -779753 | C39: -941599 | D39: -1116047 | E39: -1260823 | F39: -1338490
A40: Long Term Investments | B40: 2496552 | C40: 2581175 | D40: 3101994 | E40: 3238299 | F40: 3335009
A41: LT Investment - Affiliate Companies | B41: 1602928 | C41: 1677518 | D41: 1170787 | E41: 829026 | F41: 484460
A42: LT Investments - Other | B42: 893624 | C42: 903657 | D42: 1931207 | E42: 2409273 | F42: 2850549
A43: Note Receivable - Long Term | B43: 262485 | C43: 242873 | D43: 167244 | E43: 225091 | F43: 247392
A44: Other Long Term Assets, Total | B44: 2287383 | C44: 2753092 | D44: 3154908 | E44: 3746258 | F44: 3752382
...

Sheet FPT Corp | Income Statement 
A1: FPT Corp | Income Statement 31-Jul-2024 11:25
A3: Income Statement
A4: Industry - Annual Standardised in Millions of Vietnamese Dong
C5: 2019 | D5: 2020 | E5: 2021 | F5: 2022 | G5: 2023 | H5: ='Revenue breakdown'!G2 -> 2024F | I5: ='Revenue breakdown'!H2 -> 2025F | J5: ='Revenue breakdown'!I2 -> 2026F | K5: ='Revenue breakdown'!J2 -> 2027F | L5: ='Revenue breakdown'!K2 -> 2028F | M5: ='Revenue breakdown'!L2 -> 2029F
A6: Earnings Quality Score | C6: 67 | D6: 93 | E6: 93 | F6: 88 | G6: 96
A7: Revenue | C7: 27716960 | D7: 29830401 | E7: 35657263 | F7: 44009528 | G7: 52617901 | H7: ='Revenue breakdown'!G3 -> 60321333 | I7: ='Revenue breakdown'!H3 -> 73234495 | J7: ='Revenue breakdown'!I3 -> 87980160 | K7: ='Revenue breakdown'!J3 -> 1.0532476e+08 | L7: ='Revenue breakdown'!K3 -> 1.2617767e+08 | M7: ='Revenue breakdown'!L3 -> 1.5126305e+08
A8: Gross Revenue | C8: 27791982 | D8: 29921698 | E8: 35671052 | F8: 44023011 | G8: 52625175
A9: Sales Returns and Allowances | C9: -75022 | D9: -91298 | E9: -13790 | F9: -13483 | G9: -7274
A10: Other Revenue, Total | C10: -- | D10: -- | E10: -- | F10: -- | G10: --
A11: Total Revenue | C11: 27716960 | D11: 29830401 | E11: 35657263 | F11: 44009528 | G11: 52617901
A12: Cost of Revenue, Total | C12: 17004911 | D12: 18016743 | E12: 22025298 | F12: 26842249 | G12: 32298347
A13: Cost of Revenue | C13: 17004911 | D13: 18016743 | E13: 22025298 | F13: 26842249 | G13: 32298347
A14: Gross Profit | C14: 10712050 | D14: 11813657 | E14: 13631964 | F14: 17167279 | G14: 20319553
A16: Selling/General/Admin. Expenses, Total | C16: 6565212 | D16: 7208928 | E16: 8216937 | F16: 10372721 | G16: 11867926
A17: Selling/General/Administrative Expense | C17: 6565212 | D17: 7208928 | E17: 2696656 | F17: 4032386 | G17: 4647404
A18: Labor & Related Expense | C18: -- | D18: -- | E18: 5520281 | F18: 6340335 | G18: 7220521
A19: Research & Development | C19: -- | D19: -- | E19: -- | F19: -- | G19: --
A20: Depreciation/Amortization | C20: -- | D20: -- | E20: -- | F20: -- | G20: --
A21: Interest Expense, Net - Operating | C21: 358988 | D21: 385338 | E21: 483996 | F21: 645726 | G21: 832649
A22: Interest Expense - Operating | C22: 358988 | D22: 385338 | E22: 483996 | F22: 645726 | G22: 832649
A23: Interest/Investment Income - Operating | C23: -869071 | D23: -931614 | E23: -1306057 | F23: -1280308 | G23: -1481365
A24: Interest Income - Operating | C24: -509022 | D24: -716020 | E24: -1005088 | F24: -1349527 | G24: -1648391
A25: Investment Income - Operating | C25: -360049 | D25: -215594 | E25: -300969 | F25: 69219 | G25: 167026
A26: Interest Expense(Income) - Net Operating | C26: -- | D26: -- | E26: -- | F26: -- | G26: --
A27: Interest Exp.(Inc.),Net-Operating, Total | C27: -510084 | D27: -546276 | E27: -822061 | F27: -634583 | G27: -648716
A28: Unusual Expense (Income) | C28: -- | D28: -- | E28: -- | F28: -- | G28: --
A29: Other Operating Expenses, Total | C29: 47048 | D29: -39649 | E29: 8594 | F29: -160150 | G29: -11402
A30: Other, Net | C30: 47048 | D30: -39649 | E30: 8594 | F30: -160150 | G30: -11402
A31: Total Operating Expense | C31: 23107087 | D31: 24639746 | E31: 29428768 | F31: 36420238 | G31: 43506155
A32: Operating Income | C32: 4609873 | D32: 5190654 | E32: 6228494 | F32: 7589290 | G32: 9111746
A33: Interest Expense, Net Non-Operating | C33: -- | D33: -- | E33: -- | F33: -- | G33: --
A34: Interest/Invest Income - Non-Operating | C34: -- | D34: -- | E34: -- | F34: -- | G34: --
A35: Interest Income(Exp), Net Non-Operating | C35: -- | D35: -- | E35: -- | F35: -- | G35: --
A36: Interest Inc.(Exp.),Net-Non-Op., Total | C36: -- | D36: -- | E36: -- | F36: -- | G36: --
A37: Gain (Loss) on Sale of Assets | C37: -- | D37: -- | E37: -- | F37: -- | G37: --
A38: Other, Net | C38: 54657 | D38: 72802 | E38: 108712 | F38: 72993 | G38: 91261
A39: Other Non-Operating Income (Expense) | C39: 54657 | D39: 72802 | E39: 108712 | F39: 72993 | G39: 91261
A40: Net Income Before Taxes | C40: 4664531 | D40: 5263457 | E40: 6337206 | F40: 7662283 | G40: 9203006
A41: Provision for Income Taxes | C41: 752818 | D41: 839711 | E41: 987905 | F41: 1170940 | G41: 1414956
A42: Net Income After Taxes | C42: 3911712 | D42: 4423745 | E42: 5349301 | F42: 6491343 | G42: 7788050
...

Sheet FPT Corp | Cash Flow 
A1: FPT Corp | Cash Flow 31-Jul-2024 11:28
A3: Cash Flow
A4: Industry - Annual Standardised in Millions of Vietnamese Dong
B5: 2019 | C5: 2020 | D5: 2021 | E5: 2022 | F5: 2023 | G5: ='Revenue breakdown'!G2 -> 2024F | H5: ='Revenue breakdown'!H2 -> 2025F | I5: ='Revenue breakdown'!I2 -> 2026F | J5: ='Revenue breakdown'!J2 -> 2027F | K5: ='Revenue breakdown'!K2 -> 2028F | L5: ='Revenue breakdown'!L2 -> 2029F
A6: Cash Flow-Operating Activities (VND Millions)
A7: Net Income/Starting Line | B7: 4664531 | C7: 5263457 | D7: 6337206 | E7: 7662283 | F7: 9203006
A8: Depreciation/Depletion | B8: 1354613 | C8: 1490607 | D8: 1643916 | E8: 1833064 | F8: 2286514
A9: Depreciation | B9: 1354613 | C9: 1490607 | D9: 1643916 | E9: 1833064 | F9: 2286514
A10: Amortization | B10: -- | C10: -- | D10: -- | E10: -- | F10: --
A11: Deferred Taxes | B11: -- | C11: -- | D11: -- | E11: -- | F11: --
A12: Non-Cash Items | B12: -247143 | C12: -343816 | D12: -928199 | E12: -453084 | F12: -499761
A13: Unusual Items | B13: -903441 | C13: -1039618 | D13: -1700489 | E13: -1986716 | F13: -1976268
A14: Other Non-Cash Items | B14: 656299 | C14: 695802 | D14: 772290 | E14: 1533632 | F14: 1476507
A15: Changes in Working Capital | B15: -1873251 | C15: -70569 | D15: -1213229 | E15: -3988432 | F15: -1472663 | G15: =G16*('Revenue breakdown'!G3-'Revenue breakdown'!F3) -> -1460903.7 | H15: =H16*('Revenue breakdown'!H3-'Revenue breakdown'!G3) -> -2568791.5 | I15: =I16*('Revenue breakdown'!I3-'Revenue breakdown'!H3) -> -2864871.7 | J15: =J16*('Revenue breakdown'!J3-'Revenue breakdown'!I3) -> -3329546.8 | K15: =K16*('Revenue breakdown'!K3-'Revenue breakdown'!J3) -> -4027219.6 | L15: =L16*('Revenue breakdown'!L3-'Revenue breakdown'!K3) -> -4859172.4
C16: =C15/('Revenue breakdown'!C3-'Revenue breakdown'!B3) -> -0.03339057 | D16: =D15/('Revenue breakdown'!D3-'Revenue breakdown'!C3) -> -0.2082131 | E16: =E15/('Revenue breakdown'!E3-'Revenue breakdown'!D3) -> -0.47752699 | F16: =F15/('Revenue breakdown'!F3-'Revenue breakdown'!E3) -> -0.17107333 | G16: =MEDIAN(C16:F16) -> -0.18964321 | H16: =MEDIAN(D16:G16) -> -0.19892816 | I16: =MEDIAN(E16:H16) -> -0.19428568 | J16: =MEDIAN(F16:I16) -> -0.19196445 | K16: =MEDIAN(G16:J16) -> -0.19312507 | L16: =MEDIAN(H16:K16) -> -0.19370538
A17: Accounts Receivable | B17: -481203 | C17: 311571 | D17: -693503 | E17: -1949023 | F17: -1163209
A18: Inventories | B18: 256059 | C18: -55125 | D18: -218232 | E18: -497803 | F18: 396161
A19: Prepaid Expenses | B19: -686544 | C19: 51528 | D19: -375543 | E19: -633951 | F19: 65247
A20: Accounts Payable | B20: 305738 | C20: 1060520 | D20: 1910090 | E20: 1299835 | F20: 1380256
A21: Other Operating Cash Flow | B21: -1267300 | C21: -1439065 | D21: -1836041 | E21: -2207490 | F21: -2151118
A22: Cash from Operating Activities | B22: 3898750 | C22: 6339679 | D22: 5839694 | E22: 5053832 | F22: 9517096
A24: Cash Flow-Investing Activities (VND Millions)
A25: Capital Expenditures | B25: -3233070 | C25: -3017645 | D25: -2911001 | E25: -3215243 | F25: -3978252 | G25: =SUM(G26:G28) -> -2605512.7 | H25: =SUM(H26:H28) -> -3255914.5 | I25: =SUM(I26:I28) -> -3172483.4 | J25: =SUM(J26:J28) -> -2982576.1 | K25: =SUM(K26:K28) -> -2865528.3 | L25: =SUM(L26:L28) -> -3100526.5
A26: Technolgoy | B26: =33.8% -> 0.338 | C26: =B26*0.8 -> 0.2704 | D26: =C26*0.8 -> 0.21632 | E26: =D26*0.8 -> 0.173056 | F26: =E26*0.8 -> 0.1384448 | G26: =-$B$26*('Revenue breakdown'!G6-'Revenue breakdown'!F6) -> -1967102 | H26: =-C26*('Revenue breakdown'!H6-'Revenue breakdown'!G6) -> -2443213.6 | I26: =-$D$26*('Revenue breakdown'!I6-'Revenue breakdown'!H6) -> -2411475.2 | J26: =-$E$26*('Revenue breakdown'!J6-'Revenue breakdown'!I6) -> -2286160.4 | K26: =-$F$26*('Revenue breakdown'!K6-'Revenue breakdown'!J6) -> -2250264.3 | L26: =-$F$26*0.9*('Revenue breakdown'!L6-'Revenue breakdown'!K6) -> -2457857.5
A27: Telecommunication | B27: =35.3% -> 0.353 | C27: =B27*0.8 -> 0.2824 | D27: =C27*0.8 -> 0.22592 | E27: =D27*0.8 -> 0.180736 | F27: =E27*0.8 -> 0.1445888 | G27: =-$B$27*('Revenue breakdown'!G16-'Revenue breakdown'!F16) -> -452297.62 | H27: =-$C$27*0.8*('Revenue breakdown'!H16-'Revenue breakdown'!G16) -> -367962.82 | I27: =-$D$27*('Revenue breakdown'!I16-'Revenue breakdown'!H16) -> -396955.89 | J27: =-$E$27*('Revenue breakdown'!J16-'Revenue breakdown'!I16) -> -339935.75 | K27: =-$F$27*('Revenue breakdown'!K16-'Revenue breakdown'!J16) -> -266198.81 | L27: =-$F$27*0.9*('Revenue breakdown'!L16-'Revenue breakdown'!K16) -> -258138.69
A28: Education | B28: =30.9% -> 0.309 | C28: =B28*0.8 -> 0.2472 | D28: =C28*0.8 -> 0.19776 | E28: =D28*0.8 -> 0.158208 | F28: =E28*0.8 -> 0.1265664 | G28: =-$B$28*('Revenue breakdown'!G26-'Revenue breakdown'!F26) -> -186113 | H28: =-$C$28*0.8*('Revenue breakdown'!H26-'Revenue breakdown'!G26) -> -444738.08 | I28: =-$D$28*('Revenue breakdown'!I26-'Revenue breakdown'!H26) -> -364052.29 | J28: =-$E$28*('Revenue breakdown'!J26-'Revenue breakdown'!I26) -> -356480 | K28: =-$F$28*('Revenue breakdown'!K26-'Revenue breakdown'!J26) -> -349065.22 | L28: =-$F$28*0.9*('Revenue breakdown'!L26-'Revenue breakdown'!K26) -> -384530.25
A29: % sales growth | B29: =ABS(B25/'Revenue breakdown'!B3) -> 0.11664591 | C29: =ABS(C25/'Revenue breakdown'!C3) -> 0.10116005 | D29: =ABS(D25/'Revenue breakdown'!D3) -> 0.081638375 | E29: =ABS(E25/'Revenue breakdown'!E3) -> 0.073057884 | F29: =ABS(F25/'Revenue breakdown'!F3) -> 0.075606437 | G29: =F29 -> 0.075606437 | H29: =G29 -> 0.075606437 | I29: =H29 -> 0.075606437 | J29: =I29 -> 0.075606437 | K29: =J29 -> 0.075606437 | L29: =K29 -> 0.075606437
A33: Purchase of Fixed Assets | B33: -3233070 | C33: -3017645 | D33: -2911001 | E33: -3215243 | F33: -3978252
A34: Other Investing Cash Flow Items, Total | B34: -611999 | C34: -5126479 | D34: -7501889 | E34: 8972475 | F34: -2570122
A35: Sale of Fixed Assets | B35: 2252 | C35: 3323 | D35: 2867 | E35: 5662 | F35: 29270
A36: Sale/Maturity of Investment | B36: 120175 | C36: 31000 | D36: 27590430 | E36: 40725516 | F36: 30553191
A37: Purchase of Investments | B37: -1316846 | C37: -6055264 | D37: -36277997 | E37: -33552328 | F37: -35289808
A38: Other Investing Cash Flow | B38: 582420 | C38: 894462 | D38: 1182812 | E38: 1793625 | F38: 2137226
A39: Cash from Investing Activities | B39: -3845068 | C39: -8144124 | D39: -10412890 | E39: 5757232 | F39: -6548374
A41: Cash Flow-Financing Activities (VND Millions)
A42: Financing Cash Flow Items | B42: -- | C42: -- | D42: -- | E42: -- | F42: --
A43: Total Cash Dividends Paid | B43: -1483559 | C43: -1899079 | D43: -2254184 | E43: -2222135 | F43: -2930628
A44: Cash Dividends Paid - Common | B44: -1483559 | C44: -1899079 | D44: -2254184 | E44: -2222135 | F44: -2930628
A45: Issuance (Retirement) of Stock, Net | B45: 71445 | C45: 59634 | D45: 87611 | E45: 77029 | F45: 73051
A46: Sale/Issuance of Common | B46: 71715 | C46: 59634 | D46: 87611 | E46: 77029 | F46: 73051
...

Sheet Key metrics
A1: FPT Corp | Ratios - Key Metrics 31-Jul-2024 11:29
A3: Ratios - Key Metrics
A4: Industry - Annual Standardised in Millions of Vietnamese Dong
B5: Industry Median | C5: 2019 | D5: 2020 | E5: 2021 | F5: 2022 | G5: 2023 | H5: ='Revenue breakdown'!G2 -> 2024F | I5: ='Revenue breakdown'!H2 -> 2025F | J5: ='Revenue breakdown'!I2 -> 2026F | K5: ='Revenue breakdown'!J2 -> 2027F | L5: ='Revenue breakdown'!K2 -> 2028F | M5: ='Revenue breakdown'!L2 -> 2029F
A6: Earnings Quality Score | B6: 84 | C6: 67 | D6: 93 | E6: 93 | F6: 88 | G6: 96
A7: Profitability
A8: Gross Margin | B8: 77.8% | C8: 0.386 | D8: 0.396 | E8: 0.382 | F8: 0.39 | G8: 0.386
A9: EBITDA Margin | B9: 19.2% | C9: 0.197 | D9: 0.205 | E9: 0.198 | F9: 0.199 | G9: 0.201
A10: Operating Margin | B10: 16.2% | C10: 0.166 | D10: 0.174 | E10: 0.175 | F10: 0.172 | G10: 0.173
A11: Pretax Margin | B11: 17.3% | C11: 0.168 | D11: 0.176 | E11: 0.178 | F11: 0.174 | G11: 0.175
A12: Effective Tax Rate | B12: 24.5% | C12: 0.161 | D12: 0.16 | E12: 0.156 | F12: 0.153 | G12: 0.154
A13: Net Margin | B13: 12.6% | C13: 0.141 | D13: 0.148 | E13: 0.15 | F13: 0.147 | G13: 0.148 | H13: =G13*(1+H14) -> 0.14984858 | I13: =H13*(1+I14) -> 0.15172025 | J13: =I13*(1+J14) -> 0.1536153 | K13: =J13*(1+K14) -> 0.15553401 | L13: =K13*(1+L14) -> 0.1574767 | M13: =L13*(1+M14) -> 0.15944365
A14: DuPont/Earning Power | D14: =D13/C13-1 -> 0.04964539 | E14: =E13/D13-1 -> 0.013513514 | F14: =F13/E13-1 -> -0.02 | G14: =G13/F13-1 -> 0.0068027211 | H14: =AVERAGE(D14:G14) -> 0.012490406 | I14: =H14 -> 0.012490406 | J14: =I14 -> 0.012490406 | K14: =J14 -> 0.012490406 | L14: =K14 -> 0.012490406 | M14: =L14 -> 0.012490406
A15: Asset Turnover | B15: 1.07 | C15: 0.88 | D15: 0.79 | E15: 0.75 | F15: 0.84 | G15: 0.94
A16: x Pretax Margin | B16: 17.3% | C16: 0.168 | D16: 0.176 | E16: 0.178 | F16: 0.174 | G16: 0.175
A17: Pretax ROA | B17: 17.2% | C17: 0.148 | D17: 0.14 | E17: 0.133 | F17: 0.145 | G17: 0.164
A18: x Leverage (Assets/Equity) | B18: 1.62 | C18: 2.39 | D18: 2.65 | E18: 2.99 | F18: 2.45 | G18: 2.41
A19: Pretax ROE | B19: 29.7% | C19: 0.353 | D19: 0.354 | E19: 0.376 | F19: 0.393 | G19: 0.4
A20: x Tax Complement | B20: 0.75 | C20: 0.67 | D20: 0.67 | E20: 0.68 | F20: 0.69 | G20: 0.7
A21: ROE | B21: 24.8% | C21: 0.237 | D21: 0.238 | E21: 0.258 | F21: 0.272 | G21: 0.281
A22: x Earnings Retention | B22: 0.54 | C22: 0.55 | D22: 0.55 | E22: 0.77 | F22: 0.59 | G22: 0.6
A23: Reinvestment Rate | B23: 12.7% | C23: 0.118 | D23: 0.119 | E23: 0.18 | F23: 0.146 | G23: 0.154
A24: Liquidity
A25: Quick Ratio | B25: 1.83 | C25: 1.1 | D25: 1.07 | E25: 1.13 | F25: 1.18 | G25: 1.18
A26: Current Ratio | B26: 1.88 | C26: 1.18 | D26: 1.13 | E26: 1.18 | F26: 1.26 | G26: 1.24
A27: Times Interest Earned | B27: 30.8 | C27: 11.4 | D27: 12.1 | E27: 11.2 | F27: 10.8 | G27: 10.2
A28: Cash Cycle (Days) | B28: (8.5) | C28: 58.3 | D28: 48.4 | E28: 42.1 | F28: 46.9 | G28: 51.9
A29: Leverage
A30: Assets/Equity | B30: 1.62 | C30: 2.39 | D30: 2.65 | E30: 2.99 | F30: 2.45 | G30: 2.41
A31: Debt/Equity | B31: 0.07 | C31: 0.56 | D31: 0.81 | E31: 1.12 | F31: 0.59 | G31: 0.56
D32: =D31/C31-1 -> 0.44642857 | E32: =E31/D31-1 -> 0.38271605 | F32: =F31/E31-1 -> -0.47321429 | G32: =G31/F31-1 -> -0.050847458 | H32: =AVERAGE(C32:G32) -> 0.076270719 | I32: =AVERAGE(D32:H32) -> 0.076270719 | J32: =AVERAGE(E32:I32) -> 0.002239149 | K32: =AVERAGE(F32:J32) -> -0.073856231 | L32: =AVERAGE(G32:K32) -> 0.0060153798 | M32: =AVERAGE(H32:L32) -> 0.017387947
A33: % LT Debt to Total Capital | B33: 4.6% | C33: 0.014 | D33: 0.022 | E33: 0.055 | F33: 0.039 | G33: 0.005
A34: (Total Debt - Cash) / EBITDA | B34: (0.79) | C34: - | D34: - | E34: - | F34: - | G34: -
A35: Operating
A36: A/R Turnover | B36: 4.0 | C36: 4.3 | D36: 4.7 | E36: 5.5 | F36: 5.7 | G36: 5.7
A37: Avg. A/R Days | B37: 91.3 | C37: 85.5 | D37: 77.8 | E37: 66.2 | F37: 64.7 | G37: 64.6
A38: Inv Turnover | B38: 36.7 | C38: 13 | D38: 14 | E38: 15.7 | F38: 15.5 | G38: 18.1
A39: Avg. Inventory Days | B39: 11.1 | C39: 28.2 | D39: 26.1 | E39: 23.2 | F39: 23.7 | G39: 20.2
A40: Avg. A/P Days | B40: 103.3 | C40: 55.4 | D40: 55.5 | E40: 47.3 | F40: 41.4 | G40: 32.9
A41: Fixed Asset Turnover | B41: 10.34 | C41: 3.87 | D41: 3.4 | E41: 3.54 | F41: 3.94 | G41: 4.13
...

Sheet FCFE model
A1: FY | B1: ='Revenue breakdown'!G2 -> 2024F | C1: ='Revenue breakdown'!H2 -> 2025F | D1: ='Revenue breakdown'!I2 -> 2026F | E1: ='Revenue breakdown'!J2 -> 2027F | F1: ='Revenue breakdown'!K2 -> 2028F | G1: ='Revenue breakdown'!L2 -> 2029F
A2: VND (VND millions)
A3: Net Income | B3: ='Key metrics'!H13*'Revenue breakdown'!G3 -> 9039066.2 | C3: ='Key metrics'!I13*'Revenue breakdown'!H3 -> 11111156 | D3: ='Key metrics'!J13*'Revenue breakdown'!I3 -> 13515099 | E3: ='Key metrics'!K13*'Revenue breakdown'!J3 -> 16381583 | F3: ='Key metrics'!L13*'Revenue breakdown'!K3 -> 19870043 | G3: ='Key metrics'!M13*'Revenue breakdown'!L3 -> 24117932
A4: Depreciation Expense | B4: ='Revenue breakdown'!G3*'Key metrics'!H48 -> 1622517.9 | C4: ='Revenue breakdown'!H3*'Key metrics'!I48 -> 1969854.9 | D4: ='Revenue breakdown'!I3*'Key metrics'!J48 -> 2366482.5 | E4: ='Revenue breakdown'!J3*'Key metrics'!K48 -> 2833016.1 | F4: ='Revenue breakdown'!K3*'Key metrics'!L48 -> 3393915.8 | G4: ='Revenue breakdown'!L3*'Key metrics'!M48 -> 4068660
A5: Capital Expenditures (negative numbers in the statement means cash outflow) | B5: ='FPT Corp | Cash Flow '!G25 -> -2605512.7 | C5: ='FPT Corp | Cash Flow '!H25 -> -3255914.5 | D5: ='FPT Corp | Cash Flow '!I25 -> -3172483.4 | E5: ='FPT Corp | Cash Flow '!J25 -> -2982576.1 | F5: ='FPT Corp | Cash Flow '!K25 -> -2865528.3 | G5: ='FPT Corp | Cash Flow '!L25 -> -3100526.5
A6: Change in Working Capital (negative numbers in the statement means cash outflow) | B6: =-'FPT Corp | Balance Sheet '!G63 -> -1592291 | C6: =-'FPT Corp | Balance Sheet '!H63 -> -2669136.3 | D6: =-'FPT Corp | Balance Sheet '!I63 -> -1999420.8 | E6: =-'FPT Corp | Balance Sheet '!J63 -> 313847.16 | F6: =-'FPT Corp | Balance Sheet '!K63 -> -3064968.3 | G6: =-'FPT Corp | Balance Sheet '!L63 -> -3400960.8
A7: Net Borrowing | B7: ='FPT Corp | Cash Flow '!G50 -> 6206650.9 | C7: ='FPT Corp | Cash Flow '!H50 -> 6680036.6 | D7: ='FPT Corp | Cash Flow '!I50 -> 6694994.2 | E7: ='FPT Corp | Cash Flow '!J50 -> 6200527.2 | F7: ='FPT Corp | Cash Flow '!K50 -> 6237825.7 | G7: ='FPT Corp | Cash Flow '!L50 -> 6346288.7
A8: FCFE (FV) | B8: =SUM(B3:B7) -> 12670431 | C8: =SUM(C3:C7) -> 13835997 | D8: =SUM(D3:D7) -> 17404671 | E8: =SUM(E3:E7) -> 22746397 | F8: =SUM(F3:F7) -> 23571288 | G8: =SUM(G3:G7) -> 28031393
A11: FCFE | C11: 1 | D11: 2 | E11: 3 | F11: 4 | G11: 5
B12: FY | C12: 2024 | D12: 2025 | E12: 2026 | F12: 2027 | G12: 2028 | H12: 2029
A13: Step 1: Estimate your Future FCFE | B13: g | C13: 0.1646 | D13: 0.1646 | E13: 0.1646 | F13: 0.1646 | G13: 0.1646 | H13: ='Revenue breakdown'!P6 -> 0.090575889
A14: =B2 | B14: FCFE | C14: =B8 -> 12670431 | D14: =C8 -> 13835997 | E14: =D8 -> 17404671 | F14: =E8 -> 22746397 | G14: =F8 -> 23571288 | H14: =G8 -> 28031393
A15: PV terminal | H15: =H14/(G13-H13) -> 3.7867923e+08
A16: PV 5 years @ 20,49% | B16: DCF | C16: =C14/(1+C13)^C11 -> 10879642 | D16: =D14/(1+D13)^D11 -> 10201332 | E16: =E14/(1+E13)^E11 -> 11018830 | F16: =F14/(1+F13)^F11 -> 12365323 | G16: =(H15+G14)/(1+G13)^G11 -> 1.8776415e+08
A17: Intrinsic Value
B18: Intrinsic Value | C18: =(SUM(C16:G16)/2300) -> 100969.25
B19: Market Value | C19: =150400 -> 150400 | D19: As 24 Dec 2024
B20: SELL
A21: FCFE | B21: diff | C21: =C19/C18-1 -> 0.48956238
A24: Capital Expenditure projection | B24: =-'FPT Corp | Cash Flow '!B25 -> 3233070 | C24: =-'FPT Corp | Cash Flow '!C25 -> 3017645 | D24: =-'FPT Corp | Cash Flow '!D25 -> 2911001 | E24: =-'FPT Corp | Cash Flow '!E25 -> 3215243 | F24: =-'FPT Corp | Cash Flow '!F25 -> 3978252 | G24: =-'FPT Corp | Cash Flow '!G25 -> 2605512.7 | H24: =-'FPT Corp | Cash Flow '!H25 -> 3255914.5 | I24: =-'FPT Corp | Cash Flow '!I25 -> 3172483.4 | ... L24: =-'FPT Corp | Cash Flow '!L25 -> 3100526.5
G25: =-'FPT Corp | Cash Flow '!G26 -> 1967102 | H25: =-'FPT Corp | Cash Flow '!H26 -> 2443213.6 | I25: =-'FPT Corp | Cash Flow '!I26 -> 2411475.2 | J25: =-'FPT Corp | Cash Flow '!J26 -> 2286160.4 | K25: =-'FPT Corp | Cash Flow '!K26 -> 2250264.3 | L25: =-'FPT Corp | Cash Flow '!L26 -> 2457857.5
G26: =-'FPT Corp | Cash Flow '!G27 -> 452297.62 | H26: =-'FPT Corp | Cash Flow '!H27 -> 367962.82 | I26: =-'FPT Corp | Cash Flow '!I27 -> 396955.89 | J26: =-'FPT Corp | Cash Flow '!J27 -> 339935.75 | K26: =-'FPT Corp | Cash Flow '!K27 -> 266198.81 | L26: =-'FPT Corp | Cash Flow '!L27 -> 258138.69
G27: =-'FPT Corp | Cash Flow '!G28 -> 186113 | H27: =-'FPT Corp | Cash Flow '!H28 -> 444738.08 | I27: =-'FPT Corp | Cash Flow '!I28 -> 364052.29 | J27: =-'FPT Corp | Cash Flow '!J28 -> 356480 | K27: =-'FPT Corp | Cash Flow '!K28 -> 349065.22 | L27: =-'FPT Corp | Cash Flow '!L28 -> 384530.25

Sheet Peer Val
A1: SP_ENTITY_NAME | B1: SP_ENTITY_ID | C1: Market cap | D1: TEV | E1: Rev | F1: Gross profit | G1: EBTIDA | H1: Net income | I1: PE | J1: PV
A2: CMC Corporation (HOSE:CMG) | B2: 4971528 | C2: 411.79167 | D2: 442.67493 | E2: 288705.21 | F2: 54054.216 | G2: 29840.705 | H2: 13233.13 | I2: 35.321444 | J2: 3.888286
A3: iSoftStone Information Technology (Group) Co., Ltd. (SZSE:301236) | B3: 4277116 | C3: 8159.5572 | D3: 8219.225 | E3: 2410096.1 | F3: 463697.71 | G3: 72916.477 | H3: 73190.633 | I3: 230.4797 | J3: 5.688525
A4: Coforge Limited (NSEI:COFORGE) | B4: 4969177 | C4: 7362.988 | D4: 7515.2042 | E4: 1077664.9 | F4: 421121.72 | G4: 151723.1 | H4: 94863.628 | I4: 75.347311 | J4: 10.478438
A5: SCSK Corporation (TSE:9719) | B5: 4304803 | C5: 6476.4736 | D5: 6032.1944 | E5: 3052359 | F5: 813257.84 | G5: 498938.71 | H5: 257130.33 | I5: 24.714656 | J5: 3.260074
A6: Persistent Systems Limited (NSEI:PERSISTENT) | B6: 4966373 | C6: 10953.311 | D6: 10912.354 | E6: 1156877.2 | F6: 319098 | G6: 189746.86 | H6: 128381.84 | I6: 79.434904 | J6: 17.505478
A7: Mphasis Limited (BSE:526299) | B7: 4121483 | C7: 6519.1361 | D7: 6382.6516 | E7: 1558970.4 | F7: 626723.95 | G7: 240364.71 | H7: 182544.39 | I7: 34.980596 | J7: 6.39435
A8: Chinasoft International Limited (SEHK:354) | B8: 4968480 | C8: 1653.4923 | D8: 1776.7482 | E8: 2346515.8 | F8: 548772.52 | G8: 93991.583 | H8: 97697.886 | I8: 20.34851 | J8: 1.083784
A9: DHC Software Co.,Ltd. (SZSE:002065) | B9: 4970687 | C9: 3243.0099 | D9: 3890.0989 | E9: 1579745.8 | F9: 378817.44 | G9: 79789.613 | H9: 60103.847 | I9: 60.491803 | J9: 2.003257
A10: Digital China Holdings Limited (SEHK:861) | B10: 4290122 | C10: 724.0725 | D10: 1547.8188 | E10: 2505490 | F10: 367512.41 | G10: 59396.129 | H10: -251376.22 | I10: NM | J10: 0.844235
A11: NS Solutions Corporation (TSE:2327) | B11: 4325191 | C11: 4762.8479 | D11: 3796.5358 | E11: 1974071.5 | F11: 456557.11 | G11: 300986.3 | H11: 154051.96 | I11: 27.83365 | J11: 2.965408
A12: Otsuka Corporation (TSE:4768) | B12: 4317728 | C12: 8694.668 | D12: 7328.7588 | E12: 6211202.6 | F12: 1296283.6 | G12: 450526.2 | H12: 301532.83 | I12: 26.856028 | J12: 3.877494
A13: BIPROGY Inc. (TSE:8056) | B13: 4237387 | C13: 2918.123 | D13: 2865.4971 | E13: 2352258.6 | F13: 617542.39 | G13: 329113.6 | H13: 160438.75 | I13: NA | J13: NA
A14: Densan System Holdings Co., Ltd. (TSE:4072) | B14: 4549757 | C14: 162.26209 | D14: 73.711292 | E14: 378701.8 | F14: 67337.756 | G14: 30491.37 | H14: 12735.453 | I14: 32.842365 | J14: 1.209173
A15: NEC Networks & System Integration Corporation (TSE:1973) | B15: 4304314 | C15: 3114.9049 | D15: 2603.7772 | E15: 2284660.3 | F15: 452661.48 | G15: 183755.31 | H15: 97416.05 | I15: 31.463683 | J15: 3.201015
A16: Digital China Information Service Group Company Ltd. (SZSE:000555) | B16: 4972111 | C16: 1555.727 | D16: 1424.8386 | E16: 1652760.9 | F16: 263265.45 | G16: 49950.906 | H16: 28394.612 | I16: NM | J16: 1.880274
A17: Tata Technologies Limited (NSEI:TATATECH) | B17: 4887372 | C17: 4326.9773 | D17: 4240.3297 | E17: 600787.32 | F17: 156407.58 | G17: 103728.92 | H17: 79761.761 | I17: 57.098862 | J17: 11.463867
A18: Posco Dx Company Ltd. (KOSE:A022100) | B18: 4493939 | C18: 2056.6679 | D18: 1976.8023 | E18: 1019678.6 | F18: 129053.5 | G18: 81721.636 | H18: 63052.044 | I18: 37.815947 | J18: 5.935189
A19: OBIC Co.,Ltd. (TSE:4684) | B19: 4237129 | C19: 13046.775 | D19: 11902.02 | E19: 709156.31 | F19: 549257.73 | G19: 466731.49 | H19: 368635.45 | I19: 33.397739 | J19: 4.975809
A20: TIS Inc. (TSE:3626) | B20: 4971632 | C20: 5457.4112 | D20: 5118.0851 | E20: 3488929.6 | F20: 963668.37 | G20: 540360.71 | H20: 310588.73 | I20: 17.695475 | J20: 2.687822
A21: MFEC Public Company Limited (SET:MFEC) | B21: 4968604 | C21: 76.973645 | D21: 94.798196 | E21: 198587.25 | F21: 29586.563 | G21: 4826.0453 | H21: 19958.217 | I21: NA | J21: NA
A22: FPT Corporation (HOSE:FPT) | B22: 4968652 | C22: 8700.3069 | D22: 8422.6518 | E22: 2069127 | F22: 799038.67 | G22: 418300.68 | H22: 254234.78 | I22: 31.789438 | J22: 7.417138
A24: Minimum | E24: 198587.25 | F24: 29586.563 | G24: 4826.0453 | H24: -251376.22 | I24: 17.695475 | J24: 0.844235
A25: Median | E25: 1616253.4 | F25: 436891.6 | G25: 127726.01 | H25: 96139.839 | I25: 34.189168 | J25: 3.568784
A26: Average | E26: 1842361 | F26: 448733.87 | G26: 197945.02 | H26: 112616.77 | I26: 51.632667 | J26: 4.963471
A27: Maximum | E27: 6211202.6 | F27: 1296283.6 | G27: 540360.71 | H27: 368635.45 | I27: 230.4797 | J27: 17.505478
A34: Relative Valuation - in mn VND (Except for forecasted price) | B34: FPT Corp
A35: Net income (F) | B35: ='FCFE model'!B3 -> 9039066.2
A36: # no. of shares outstanding (A) | B36: 2300.9
A37: EPS (F) | B37: =B35/B36 -> 3928.4915
A38: current P/E (average in the industry) | B38: =I25 -> 34.189168
A39: Forecasted price (in VND) | B39: =B37*B38 -> 134311.85
B42: Price | C42: Weighted | D42: Weighted price
A43: FCFE Model | B43: ='FCFE model'!C18 -> 100969.25 | C43: =60% -> 0.6 | D43: =C43*B43 -> 60581.552
A44: Peers Model | B44: =B39 -> 134311.85 | C44: =40% -> 0.4 | D44: =C44*B44 -> 53724.742
A45: Final Price | D45: =SUM(D43:D44) -> 114306.29
D47: =D45/'FCFE model'!C19-1 -> -0.23998475 | E47: hold

Sheet Peer Selection
A2: Peers | D2: Market cap ($M) | E2: Revenue ($M)
A3: CMC Corporation (HOSE:CMG)
A4: iSoftStone Information Technology (Group) Co., Ltd. (SZSE:301236)
A5: Coforge Limited (NSEI:COFORGE)

Sheet Revenue breakdown
B1: Historical | G1: Forecast
A2: FPT Revenue Breakdown (mil VND) | B2: 2019 | C2: 2020 | D2: 2021 | E2: 2022 | F2: 2023 | G2: 2024F | H2: 2025F | I2: 2026F | J2: 2027F | K2: 2028F | L2: 2029F
A3: Total Revenue (1) + (2) + (3) | B3: ='FPT Corp | Income Statement '!C7 -> 27716960 | C3: ='FPT Corp | Income Statement '!D7 -> 29830401 | D3: ='FPT Corp | Income Statement '!E7 -> 35657263 | E3: ='FPT Corp | Income Statement '!F7 -> 44009528 | F3: ='FPT Corp | Income Statement '!G7 -> 52617901 | G3: =SUM(G6,G16,G26) -> 60321333 | H3: =SUM(H6,H16,H26) -> 73234495 | I3: =SUM(I6,I16,I26) -> 87980160 | J3: =SUM(J6,J16,J26) -> 1.0532476e+08 | K3: =SUM(K6,K16,K26) -> 1.2617767e+08 | L3: =SUM(L6,L16,L26) -> 1.5126305e+08 | N3: =(L3/B3)^(1/(COUNT(B2:L2)))-1 -> 0.4040981 | P3: terminal growth
A4: %growth | C4: =C3/B3-1 -> 0.076250823 | D4: =D3/C3-1 -> 0.19533301 | E4: =E3/D3-1 -> 0.23423741 | F4: =F3/E3-1 -> 0.19560248 | G4: =G3/F3-1 -> 0.14640326 | H4: =H3/G3-1 -> 0.21407288 | I4: =I3/H3-1 -> 0.20134863 | J4: =J3/I3-1 -> 0.19714219 | ... L4: =L3/K3-1 -> 0.19880995 | N4: =N8*L7+N17*L17+N27*L27 -> 0.17972767 | P4: 0.058 | Q4: GDP
P5: 0.034 | Q5: inflation
A6: Technology (1) | B6: =B7*B3 -> 15770950 | C6: =16805*10^3 -> 16805000 | D6: =20736.263*10^3 -> 20736263 | E6: =25763*10^3 -> 25763000 | F6: =$F$3*F7 -> 31465505 | G6: =SUM(G9,G12) -> 37285333 | H6: =H9+H12 -> 46320887 | I6: =I9+I12 -> 57468609 | J6: =J9+J12 -> 70679132 | K6: =K9+K12 -> 86933006 | L6: =L9+L12 -> 106658939 | P6: =AVERAGE(P4:P5,N4) -> 0.090575889
A7: % weight | B7: =56.9% -> 0.569 | C7: =C6/C3 -> 0.56335146 | D7: =D6/D3 -> 0.58154388 | E7: =E6/E3 -> 0.58539596 | F7: =59.8% -> 0.598 | G7: =G6/$G$3 -> 0.61811189 | H7: =H6/H3 -> 0.63250094 | I7: =I6/I3 -> 0.65319964 | J7: =J6/J3 -> 0.67105903 | K7: =K6/K3 -> 0.68897298 | L7: =L6/L3 -> 0.70512224
A8: % growth | C8: =C6/B6-1 -> 0.065566738 | D8: =D6/C6-1 -> 0.23393413 | E8: =E6/D6-1 -> 0.24241287 | F8: =F6/E6-1 -> 0.22134475 | G8: =G6/F6-1 -> 0.18495901 | H8: =H6/G6-1 -> 0.24233533 | I8: =I6/H6-1 -> 0.24066297 | J8: =J6/I6-1 -> 0.22987373 | ... L8: =L6/K6-1 -> 0.22690959 | N8: =(L6/B6)^(1/(COUNT(B6:L6)))-1 -> 0.18978152
A9: FPT Software | B9: =B6-B12 -> 10835592 | C9: =C6-C12 -> 12002877 | D9: =D6-D12 -> 14540759 | E9: =E6-E12 -> 19177406 | F9: =F6-F12 -> 24740499 | G9: =21987358*4/3 -> 29316477 | H9: =G9*(1+H10) -> 36176533 | I9: =H9*(1+I10) -> 44573106 | J9: =I9*(1+J10) -> 54428220 | K9: =J9*(1+K10) -> 66456857 | L9: =K9*(1+L10) -> 80924515 | M9: =L9/L6 -> 0.75872229
A10: %growth | C10: =C9/B9-1 -> 0.1077269 | D10: =D9/C9-1 -> 0.21143947 | E10: =E9/D9-1 -> 0.31887242 | F10: =F9/E9-1 -> 0.29008578 | G10: =G9/F9-1 -> 0.18495902 | H10: 0.234 | I10: 0.2321 | J10: 0.2211 | K10: 0.221 | L10: 0.2177
A11: %weight in Technology | B11: =B9/B6 -> 0.6870602 | C11: =C9/C6 -> 0.71424439 | D11: =D9/D6 -> 0.7012237 | E11: =E9/E6 -> 0.74437783 | F11: =F9/F6 -> 0.7862737 | G11: =G9/G6 -> 0.78627371 | H11: =H9/H6 -> 0.78099828 | I11: =I9/I6 -> 0.77560789 | ... L11: =L9/L6 -> 0.75872229
A12: FPT Information System | B12: 4935358 | C12: 4802123 | D12: 6195504 | E12: 6585594 | F12: =6725006 -> 6725006 | G12: =5976642*4/3 -> 7968856 | H12: =G12*(1+H13) -> 10144354 | I12: =H12*(1+I13) -> 12895502 | J12: =I12*(1+J13) -> 16250912 | K12: =J12*(1+K13) -> 20476149 | L12: =K12*(1+L13) -> 25734424 | M12: =L12/L6 -> 0.24127771
A13: %growth | C13: =C12/B12-1 -> -0.026996015 | D13: =D12/C12-1 -> 0.29015937 | E13: =E12/D12-1 -> 0.062963401 | F13: =F12/E12-1 -> 0.021169237 | G13: =G12/F12-1 -> 0.18495894 | H13: 0.273 | I13: 0.2712 | J13: 0.2602 | K13: 0.26 | L13: 0.2568
A14: %weight in Technology | B14: =B12/B6 -> 0.3129398 | C14: =C12/C6 -> 0.28575561 | D14: =D12/D6 -> 0.2987763 | E14: =E12/E6 -> 0.25562217 | F14: =F12/F6 -> 0.2137263 | G14: =G12/G6 -> 0.21372629 | H14: =H12/H6 -> 0.21900172 | I14: =I12/I6 -> 0.22439211 | ... L14: =L12/L6 -> 0.24127771
A16: Telecommunication (2) | B16: =B17*B3 -> 10393860 | C16: =11466.401*10^3 -> 11466401 | D16: =12686*10^3 -> 12686000 | E16: =E3-E6-E26 -> 14729528 | F16: =$F$3*F17 -> 15785370 | G16: =SUM(G19,G22) -> 17066667 | H16: =SUM(H19,H22) -> 18695397 | I16: =SUM(I19,I22) -> 20452461 | J16: =SUM(J19,J22) -> 22333303 | K16: =SUM(K19,K22) -> 24174378 | L16: =SUM(L19,L22) -> 26158077
A17: % weight | B17: =37.5% -> 0.375 | C17: =C16/C3 -> 0.38438642 | D17: =D16/D3 -> 0.35577604 | E17: =E16/E3 -> 0.33468952 | F17: 0.3 | G17: =G16/$G$3 -> 0.2829292 | H17: =H16/$H$3 -> 0.2552813 | I17: =I16/$I$3 -> 0.23246674 | J17: =J16/$J$3 -> 0.21204228 | K17: =K16/$K$3 -> 0.19158998 | L17: =L16/$L$3 -> 0.17293105 | N17: =(L16/B16)^(1/(COUNT(B16:L16)))-1 -> 0.087524366
A18: % growth | C18: =C16/B16-1 -> 0.10318986 | D18: =D16/C16-1 -> 0.10636284 | E18: =E16/D16-1 -> 0.16108529 | F18: =F16/E16-1 -> 0.071682019 | G18: =G16/F16-1 -> 0.081169864 | H18: =H16/G16-1 -> 0.095433434 | I18: =I16/H16-1 -> 0.093983773 | J18: =J16/I16-1 -> 0.091961617 | ... L18: =L16/K16-1 -> 0.082057945
A19: FPT Telecom | B19: =9789.86*10^3 -> 9789860 | C19: =10867.2*10^3 -> 10867200 | D19: =12079*10^3 -> 12079000 | E19: =E74*$E$16/$E$76 -> 13954105 | F19: 15185852 | G19: =12320000*4/3 -> 16426667 | H19: =G19*(1+H20) -> 18054412 | I19: =H19*(1+I20) -> 19810489 | J19: =I19*(1+J20) -> 21690341 | K19: =J19*(1+K20) -> 23530426 | L19: =K19*(1+L20) -> 25513134
A20: %growth | C20: =C19/B19-1 -> 0.11004652 | D20: =D19/C19-1 -> 0.11150986 | E20: =E19/D19-1 -> 0.15523681 | F20: =F19/E19-1 -> 0.088271272 | G20: =G19/F19-1 -> 0.081708597 | H20: =AVERAGE(C20:G20,$M$20) -> 0.099091619 | I20: =AVERAGE(D20:H20,$M$20) -> 0.097265803 | J20: =AVERAGE(E20:I20,$M$20) -> 0.094891793 | K20: =AVERAGE(F20:J20,$M$20) -> 0.084834291 | L20: =AVERAGE(G20:K20,$M$20) -> 0.08426146 | M20: 0.047776659 | N20: >> CAGR of telecommunication services revenue growth
A21: %weight in Telecommunication | B21: =B19/B16 -> 0.94188877 | C21: =C19/C16 -> 0.94774289 | D21: =D19/D16 -> 0.95215198 | E21: =E19/E16 -> 0.94735591 | F21: =F19/F16 -> 0.96202064 | G21: =G19/G16 -> 0.9625 | H21: =H19/H16 -> 0.96571426 | I21: =I19/I16 -> 0.96861147 | ... L21: =L19/L16 -> 0.9753444
A22: FPT Online | B22: =B16-B19 -> 604000 | C22: =599.201*10^3 -> 599201 | D22: =D16-D19 -> 607000 | E22: =E16-E19 -> 775422.63 | F22: =F16-F19 -> 599518.3 | G22: =480000*4/3 -> 640000 | H22: =G22*(1+H23) -> 640985.6 | I22: =H22*(1+I23) -> 641972.72 | J22: =I22*(1+J23) -> 642961.36 | K22: =J22*(1+K23) -> 643951.52 | L22: =K22*(1+L23) -> 644943.2 | M22: >> despite digital ads is growing but market share of FPT online as agency is limited
A23: %growth | C23: =C22/B22-1 -> -0.0079453642 | D23: =D22/C22-1 -> 0.013015666 | E23: =E22/D22-1 -> 0.27746727 | F23: =F22/E22-1 -> -0.22684962 | G23: =G22/F22-1 -> 0.06752371 | H23: =7.7%*2% -> 0.00154 | I23: =7.7%*2% -> 0.00154 | J23: =7.7%*2% -> 0.00154 | K23: =7.7%*2% -> 0.00154 | L23: =7.7%*2% -> 0.00154
A24: %weight in Telecommunication | B24: =B22/B16 -> 0.058111231 | C24: =C22/C16 -> 0.052257112 | D24: =D22/D16 -> 0.047848021 | E24: =E22/E16 -> 0.052644092 | F24: =F22/F16 -> 0.037979362 | G24: =G22/G16 -> 0.0375 | H24: =H22/H16 -> 0.034285744 | I24: =I22/I16 -> 0.031388531 | ... L24: =L22/L16 -> 0.024655604
A26: Education, Investment and Others(3) | B26: =B27*B3 -> 1552149.8 | C26: =1559*10^3 -> 1559000 | D26: =2235*10^3 -> 2235000 | E26: =3517*10^3 -> 3517000 | F26: =$F$3*F27 -> 5367025.9 | G26: =4477000*4/3 -> 5969333.3 | H26: =H29*(H31/10^6) -> 8218211.2 | I26: =I29*(I31/10^6) -> 10059090 | J26: =J29*(J31/10^6) -> 12312327 | K26: =K29*(K31/10^6) -> 15070288 | L26: =L29*(L31/10^6) -> 18446032
A27: % weight | B27: =5.6% -> 0.056 | C27: =C26/C3 -> 0.05226212 | D27: =D26/D3 -> 0.062680077 | E27: =E26/E3 -> 0.079914513 | F27: =10.2% -> 0.102 | G27: =G26/$G$3 -> 0.098958909 | H27: =H26/H3 -> 0.11221776 | I27: =I26/I3 -> 0.11433362 | J27: =J26/J3 -> 0.11689869 | K27: =K26/K3 -> 0.11943704 | L27: =L26/L3 -> 0.12194672 | N27: =(L26/B26)^(1/(COUNT(B26:L26)))-1 -> 0.25234644
A28: % growth | C28: =C26/B26-1 -> 0.0044133886 | D28: =D26/C26-1 -> 0.43361129 | E28: =E26/D26-1 -> 0.57360179 | F28: =F26/E26-1 -> 0.52602386 | G28: =G26/F26-1 -> 0.11222369 | H28: =H26/G26-1 -> 0.37673853 | I28: =I26/H26-1 -> 0.224 | J28: =J26/I26-1 -> 0.224 | ... L28: =L26/K26-1 -> 0.224
A29: Active students | B29: 39833 | C29: 52005 | D29: 74313 | E29: 108100 | F29: 145000 | G29: =F29*(1+G30) -> 174000 | H29: =G29*(1+H30) -> 208800 | I29: =H29*(1+I30) -> 250560 | J29: =I29*(1+J30) -> 300672 | K29: =J29*(1+K30) -> 360806.4 | L29: =K29*(1+L30) -> 432967.68
C30: =C29/B29-1 -> 0.30557578 | D30: =D29/C29-1 -> 0.42895875 | E30: =E29/D29-1 -> 0.454658 | F30: =F29/E29-1 -> 0.3413506 | G30: =20% -> 0.2 | H30: =20% -> 0.2 | I30: =20% -> 0.2 | J30: =20% -> 0.2 | K30: =20% -> 0.2 | L30: =20% -> 0.2
A31: Average tuition fee | B31: =B26*10^6/B29 -> 38966429 | C31: =C26*10^6/C29 -> 29977887 | D31: =D26*10^6/D29 -> 30075492 | E31: =E26*10^6/E29 -> 32534690 | F31: =F26*10^6/F29 -> 37013972 | G31: =F31*(1+G32) -> 38587499 | H31: =G31*(1+H32) -> 39359249 | I31: =H31*(1+I32) -> 40146434 | J31: =I31*(1+J32) -> 40949363 | K31: =J31*(1+K32) -> 41768350 | L31: =K31*(1+L32) -> 42603717
C32: =C31/B31-1 -> -0.230674 | D32: =D31/C31-1 -> 0.003255892 | E32: =E31/D31-1 -> 0.081767528 | F32: =F31/E31-1 -> 0.1376771 | G32: =MEDIAN(C32:F32) -> 0.04251171 | H32: =2% -> 0.02 | I32: =2% -> 0.02 | J32: =2% -> 0.02 | K32: =2% -> 0.02 | L32: =2% -> 0.02
A33: Test | G33: =1-SUM(G7,G17,G27) -> 0 | H33: =1-SUM(H7,H17,H27) -> 0 | I33: =1-SUM(I7,I17,I27) -> 0 | J33: =1-SUM(J7,J17,J27) -> 0 | K33: =1-SUM(K7,K17,K27) -> 0 | L33: =1-SUM(L7,L17,L27) -> 0
G44: =1201*10^6*25000 -> 30025000000000
G45: =G44/10^6 -> 30025000
G46: =G22/G45 -> 0.02131557
G48: =11.7% -> 0.117
G49: =17.08% -> 0.1708 | H49: >> market share
A61: Digital transformation | B61: 0.16 | C61: CAGR
E62: 45559499
E65: Revenue
A66: Global IT services | E66: 18271974 | F66: 24288049 | G66: 22668000 | H66: 30224000
...

Sheet Revenue assumption
B1: ='Revenue breakdown'!B9 -> 10835592 | C1: ='Revenue breakdown'!C9 -> 12002877 | D1: ='Revenue breakdown'!D9 -> 14540759 | E1: ='Revenue breakdown'!E9 -> 19177406 | F1: ='Revenue breakdown'!F9 -> 24740499
A2: Revenue by foreign markets | B2: ='Revenue breakdown'!B2 -> 2019 | C2: ='Revenue breakdown'!C2 -> 2020 | D2: ='Revenue breakdown'!D2 -> 2021 | E2: ='Revenue breakdown'!E2 -> 2022 | F2: ='Revenue breakdown'!F2 -> 2023 | G2: ='Revenue breakdown'!G2 -> 2024F | H2: ='Revenue breakdown'!H2 -> 2025F | I2: ='Revenue breakdown'!I2 -> 2026F | ... L2: ='Revenue breakdown'!L2 -> 2029F
A3: Japan | B3: 0.51 | C3: =50% -> 0.5 | D3: =(D1-(D1*SUM(D4:D6)))/D1 -> 0.43422679 | E3: =1-SUM(E4:E6) -> 0.39460628 | F3: =1-SUM(F4:F6) -> 0.43949375
A4: US | B4: 0.25 | C4: 0.24 | D4: =(C4*$C$1*1.52)/$D$1 -> 0.30112937 | E4: =(D4*$D$1*1.5)/$E$1 -> 0.34248502 | F4: =(E4*$E$1*1.086)/$F$1 -> 0.28830543
A5: EU | B5: 0.09 | C5: 0.08 | D5: =(C5*$C$1*1.15)/$D$1 -> 0.075942713 | E5: =(D5*$D$1*1.194)/$E$1 -> 0.068752366 | F5: =(E5*$E$1*1.219)/$F$1 -> 0.064964001
A6: APAC | B6: 0.15 | C6: 0.18 | D6: =(C6*$C$1*1.27)/$D$1 -> 0.18870113 | E6: =(D6*$D$1*1.357)/$E$1 -> 0.19415634 | F6: =(E6*$E$1*1.377)/$F$1 -> 0.20723682
A7: Test | B7: =SUM(B3:B6) -> 1 | C7: =SUM(C3:C6) -> 1 | D7: =SUM(D3:D6) -> 1 | E7: =SUM(E3:E6) -> 1 | F7: =SUM(F3:F6) -> 1 | G7: =SUM(G3:G6) -> 0
B8: =B7-1 -> 0 | C8: =C7-1 -> 0 | D8: =D7-1 -> 0
A9: Revenue by foreign markets | B9: =B2 -> 2019 | C9: =C2 -> 2020 | D9: =D2 -> 2021 | E9: =E2 -> 2022 | F9: =F2 -> 2023 | G9: =G2 -> 2024F | H9: =H2 -> 2025F | I9: =I2 -> 2026F | ... L9: =L2 -> 2029F | N9: weighted
A10: Japan | B10: =B3*$B$1 -> 5526152 | C10: =C3*$C$1 -> 6001438.5 | D10: =D3*$D$1 -> 6313987.1 | E10: =E3*$E$1 -> 7567524.8 | F10: =F3*$F$1 -> 10873295 | G10: =F10*(1+G11) -> 12975797 | H10: =G10*(1+H11) -> 15484848 | I10: =H10*(1+I11) -> 18811539 | J10: =I10*(1+J11) -> 23465262 | K10: =J10*(1+K11) -> 29499522 | L10: =K10*(1+L11) -> 36025447 | M10: =(L10/F10)^(1/(COUNT(F10:L10)))-1 -> 0.18664599 | N10: =F10/$F$1 -> 0.43949375 | P10: =N10*F11+N12*F13+N14*F15+N16*F17 -> 0.30913651
A11: %growth | C11: =C10/B10-1 -> 0.086006765 | D11: =D10/C10-1 -> 0.052078948 | E11: =E10/D10-1 -> 0.19853346 | F11: =F10/E10-1 -> 0.43683634 | G11: =AVERAGE(B11:F11) -> 0.19336388 | H11: =AVERAGE(C11:G11) -> 0.19336388 | I11: =AVERAGE(D11:H11) -> 0.2148353 | J11: =AVERAGE(E11:I11) -> 0.24738657 | K11: =AVERAGE(F11:J11) -> 0.25715719 | L11: =AVERAGE(G11:K11) -> 0.22122136
A12: US | B12: =B4*$B$1 -> 2708898.1 | C12: =C4*$C$1 -> 2880690.5 | D12: =D4*$D$1 -> 4378649.5 | E12: =E4*$E$1 -> 6567974.3 | F12: =F4*$F$1 -> 7132820.1 | G12: =F12*(1+G13) -> 9218131.8 | H12: =G12*(1+H13) -> 11913094 | I12: =H12*(1+I13) -> 15941408 | J12: =I12*(1+J13) -> 20752050 | K12: =J12*(1+K13) -> 26191663 | L12: =K12*(1+L13) -> 33979728 | M12: =(L12/F12)^(1/(COUNT(F12:L12)))-1 -> 0.24983083 | N12: =F12/$F$1 -> 0.28830543
A13: %growth | C13: =C12/B12-1 -> 0.063417824 | D13: =D12/C12-1 -> 0.52 | E13: =E12/D12-1 -> 0.5 | F13: =F12/E12-1 -> 0.086 | G13: =AVERAGE(B13:F13) -> 0.29235446 | H13: =AVERAGE(C13:G13) -> 0.29235446 | I13: =AVERAGE(D13:H13) -> 0.33814178 | J13: =AVERAGE(E13:I13) -> 0.30177014 | K13: =AVERAGE(F13:J13) -> 0.26212417 | L13: =AVERAGE(G13:K13) -> 0.297349
A14: EU | B14: =B5*$B$1 -> 975203.3 | C14: =C5*$C$1 -> 960230.16 | D14: =D5*$D$1 -> 1104264.7 | E14: =E5*$E$1 -> 1318492 | F14: =F5*$F$1 -> 1607241.8 | G14: =F14*(1+G15) -> 1827291.7 | H14: =G14*(1+H15) -> 2077469 | I14: =H14*(1+I15) -> 2425163.8 | J14: =I14*(1+J15) -> 2839472.9 | K14: =J14*(1+K15) -> 3311407.6 | L14: =K14*(1+L15) -> 3826815.1 | M14: =(L14/F14)^(1/(COUNT(F14:L14)))-1 -> 0.13193717 | N14: =F14/$F$1 -> 0.064964001
A15: %growth | C15: =C14/B14-1 -> -0.015353867 | D15: =D14/C14-1 -> 0.15 | E15: =E14/D14-1 -> 0.194 | F15: =F14/E14-1 -> 0.219 | G15: =AVERAGE(B15:F15) -> 0.13691153 | H15: =AVERAGE(C15:G15) -> 0.13691153 | I15: =AVERAGE(D15:H15) -> 0.16736461 | J15: =AVERAGE(E15:I15) -> 0.17083754 | K15: =AVERAGE(F15:J15) -> 0.16620504 | L15: =AVERAGE(G15:K15) -> 0.15564605
A16: APAC | B16: =B6*$B$1 -> 1625338.8 | C16: =C6*$C$1 -> 2160517.9 | D16: =D6*$D$1 -> 2743857.7 | E16: =E6*$E$1 -> 3723414.9 | F16: =F6*$F$1 -> 5127142.3 | G16: =F16*(1+G17) -> 6836111.5 | H16: =G16*(1+H17) -> 9114710.9 | I16: =H16*(1+I17) -> 12160184 | J16: =I16*(1+J17) -> 16379192 | K16: =J16*(1+K17) -> 22029084 | L16: =K16*(1+L17) -> 29486630 | M16: =(L16/F16)^(1/(COUNT(F16:L16)))-1 -> 0.28391325 | N16: =F16/$F$1 -> 0.20723682
A17: %growth | C17: =C16/B16-1 -> 0.32927228 | D17: =D16/C16-1 -> 0.27 | E17: =E16/D16-1 -> 0.357 | F17: =F16/E16-1 -> 0.377 | G17: =AVERAGE(B17:F17) -> 0.33331807 | H17: =AVERAGE(C17:G17) -> 0.33331807 | I17: =AVERAGE(D17:H17) -> 0.33412723 | J17: =AVERAGE(E17:I17) -> 0.34695267 | K17: =AVERAGE(F17:J17) -> 0.34494321 | L17: =AVERAGE(G17:K17) -> 0.33853185 | N17: =1-SUM(N10:N16) -> 0
B19: =E9 -> 2022 | C19: =F9 -> 2023 | D19: =G9 -> 2024F | E19: =H9 -> 2025F
A20: 5G coverage | B20: 0.08 | C20: 0.14 | D20: 0.2 | E20: 0.25
C21: =C20/B20-1 -> 0.75 | D21: =D20/C20-1 -> 0.42857143 | E21: =E20/D20-1 -> 0.25
A22: Mobile broadband subscribers | B22: 0.85 | C22: 0.9 | D22: 0.95 | E22: 1
C23: =C22/B22-1 -> 0.058823529 | D23: =D22/C22-1 -> 0.055555556 | E23: =E22/D22-1 -> 0.052631579
A24: Internet users | B24: 0.74 | C24: 0.76 | D24: 0.78 | E24: 0.8
C25: =C24/B24-1 -> 0.027027027 | D25: =D24/C24-1 -> 0.026315789 | E25: =E24/D24-1 -> 0.025641026
C26: =AVERAGE(C21,C23,C25) -> 0.27861685 | D26: =AVERAGE(D21,D23,D25) -> 0.17014759 | E26: =AVERAGE(E21,E23,E25) -> 0.1094242
A27: Vietnam telecommunications market size | B27: VND million | D27: =6.3*10^3*25000 -> 157500000 | E27: =D27*1.01 -> 159075000 | F27: =E27*1.01 -> 160665750 | G27: =F27*1.01 -> 1.6227241e+08 | H27: =G27*1.01 -> 1.6389513e+08 | I27: =H27*1.01 -> 1.6553408e+08 | J27: =I27*1.01 -> 1.6718942e+08 | K27: =J27*1.01 -> 168861318 | L27: =K27*1.01 -> 1.7054993e+08
A78: IT services revenue | B78: 2024 | C78: 2025 | D78: 2026 | E78: 2027 | F78: 2028 | G78: 2029 | I78: Global share | J78: 0.0014103673 | K78: 0.0014712638 | L78: 0.0015296057 | M78: 0.0015748404 | N78: 0.001619474 | O78: 0.0016662381
A79: Albania | B79: 0.13 | C79: 0.14 | D79: 0.15 | E79: 0.16 | F79: 0.17 | G79: 0.18 | I79: % growth | K79: 0.043177756 | L79: 0.039654289 | M79: 0.029572831 | N79: 0.028341659 | O79: 0.028876052 | Q79: =(O78/J78)^(1/(COUNT(J78:O78)))-1 -> 0.028176022
A80: Algeria | B80: 1.15 | C80: 1.21 | D80: 1.27 | E80: 1.31 | F80: 1.35 | G80: 1.41 | I80: SEA share | J80: 0.064863103 | K80: 0.06642621 | L80: 0.067885841 | M80: 0.068929775 | N80: 0.069975787 | O80: 0.071248568
A81: Angola | B81: 0.87 | C81: 0.92 | D81: 0.98 | E81: 1.04 | F81: 1.11 | G81: 1.17 | I81: % growth | K81: 0.024098551 | L81: 0.021973723 | M81: 0.015377781 | N81: 0.015175044 | O81: 0.018188881
A82: Argentina | B82: 3.11 | C82: 3.14 | D82: 3.28 | E82: 3.45 | F82: 3.61 | G82: 3.75
A83: Armenia | B83: 0.13 | C83: 0.14 | D83: 0.16 | E83: 0.17 | F83: 0.18 | G83: 0.19 | I83: Growth rev | K83: =C91/B91-1 -> 0 | L83: =D91/C91-1 -> 0 | M83: =E91/D91-1 -> 1 | N83: =F91/E91-1 -> 0 | O83: =G91/F91-1 -> 0
A84: Australia | B84: 35.9 | C84: 38.48 | D84: 41.16 | E84: 43.54 | F84: 46.08 | G84: 48.26 | K84: =K83+K79 -> 0.043177756 | L84: =L83+L79 -> 0.039654289 | M84: =M83+M79 -> 1.0295728 | N84: =N83+N79 -> 0.028341659 | O84: =O83+O79 -> 0.028876052 | Q84: 0.239
A85: Austria | B85: 8.06 | C85: 8.58 | D85: 9.1 | E85: 9.53 | F85: 9.95 | G85: 10.36 | K85: =AVERAGE(K84,$Q$7,$Q$8) -> 0.043177756 | L85: =AVERAGE(L84,$Q$7,$Q$8) -> 0.039654289 | M85: =AVERAGE(M84,$Q$7,$Q$8) -> 1.0295728 | N85: =AVERAGE(N84,$Q$7,$Q$8) -> 0.028341659 | O85: =AVERAGE(O84,$Q$7,$Q$8) -> 0.028876052 | Q85: ='Revenue assumption'!$P$10 -> 0.30913651
A86: Azerbaijan | B86: 0.36 | C86: 0.39 | D86: 0.41 | E86: 0.43 | F86: 0.46 | G86: 0.48
A87: Bahrain | B87: 0.15 | C87: 0.16 | D87: 0.17 | E87: 0.18 | F87: 0.19 | G87: 0.2
A88: Bangladesh | B88: 1.85 | C88: 2.11 | D88: 2.42 | E88: 2.72 | F88: 3.05 | G88: 3.3
A89: Belarus | B89: 0.57 | C89: 0.58 | D89: 0.61 | E89: 0.64 | F89: 0.67 | G89: 0.69
A90: Belgium | B90: 9.66 | C90: 10.17 | D90: 10.7 | E90: 11.15 | F90: 11.65 | G90: 12.14
A91: Belize | B91: 0.01 | C91: 0.01 | D91: 0.01 | E91: 0.02 | F91: 0.02 | G91: 0.02
...

Sheet Exhibit
B1: ='Revenue breakdown'!B2 -> 2019 | C1: ='Revenue breakdown'!C2 -> 2020 | D1: ='Revenue breakdown'!D2 -> 2021 | E1: ='Revenue breakdown'!E2 -> 2022 | F1: ='Revenue breakdown'!F2 -> 2023 | G1: ='Revenue breakdown'!G2 -> 2024F | H1: ='Revenue breakdown'!H2 -> 2025F | I1: ='Revenue breakdown'!I2 -> 2026F | ... L1: ='Revenue breakdown'!L2 -> 2029F
A2: FPT Software | B2: ='Revenue breakdown'!B9 -> 10835592 | C2: ='Revenue breakdown'!C9 -> 12002877 | D2: ='Revenue breakdown'!D9 -> 14540759 | E2: ='Revenue breakdown'!E9 -> 19177406 | F2: ='Revenue breakdown'!F9 -> 24740499 | G2: ='Revenue breakdown'!G9 -> 29316477 | H2: ='Revenue breakdown'!H9 -> 36176533 | I2: ='Revenue breakdown'!I9 -> 44573106 | ... L2: ='Revenue breakdown'!L9 -> 80924515 | M2: =(L2/B2)^(1/(COUNT(B2:L2)))-1 -> 0.20056123
A3: FPT IS | B3: ='Revenue breakdown'!B12 -> 4935358 | C3: ='Revenue breakdown'!C12 -> 4802123 | D3: ='Revenue breakdown'!D12 -> 6195504 | E3: ='Revenue breakdown'!E12 -> 6585594 | F3: ='Revenue breakdown'!F12 -> 6725006 | G3: ='Revenue breakdown'!G12 -> 7968856 | H3: ='Revenue breakdown'!H12 -> 10144354 | I3: ='Revenue breakdown'!I12 -> 12895502 | ... L3: ='Revenue breakdown'!L12 -> 25734424
A4: FPT Telecom | B4: ='Revenue breakdown'!B19 -> 9789860 | C4: ='Revenue breakdown'!C19 -> 10867200 | D4: ='Revenue breakdown'!D19 -> 12079000 | E4: ='Revenue breakdown'!E19 -> 13954105 | F4: ='Revenue breakdown'!F19 -> 15185852 | G4: ='Revenue breakdown'!G19 -> 16426667 | H4: ='Revenue breakdown'!H19 -> 18054412 | I4: ='Revenue breakdown'!I19 -> 19810489 | ... L4: ='Revenue breakdown'!L19 -> 25513134
A5: FPT Online | B5: ='Revenue breakdown'!B22 -> 604000 | C5: ='Revenue breakdown'!C22 -> 599201 | D5: ='Revenue breakdown'!D22 -> 607000 | E5: ='Revenue breakdown'!E22 -> 775422.63 | F5: ='Revenue breakdown'!F22 -> 599518.3 | G5: ='Revenue breakdown'!G22 -> 640000 | H5: ='Revenue breakdown'!H22 -> 640985.6 | I5: ='Revenue breakdown'!I22 -> 641972.72 | ... L5: ='Revenue breakdown'!L22 -> 644943.2
A6: FPT Education & Investment | B6: ='Revenue breakdown'!B26 -> 1552149.8 | C6: ='Revenue breakdown'!C26 -> 1559000 | D6: ='Revenue breakdown'!D26 -> 2235000 | E6: ='Revenue breakdown'!E26 -> 3517000 | F6: ='Revenue breakdown'!F26 -> 5367025.9 | G6: ='Revenue breakdown'!G26 -> 5969333.3 | H6: ='Revenue breakdown'!H26 -> 8218211.2 | I6: ='Revenue breakdown'!I26 -> 10059090 | ... L6: ='Revenue breakdown'!L26 -> 18446032
A7: Test | B7: =SUM(B2:B6)-'Revenue breakdown'!B3 -> 0 | C7: =SUM(C2:C6)-'Revenue breakdown'!C3 -> 0 | D7: =SUM(D2:D6)-'Revenue breakdown'!D3 -> 0 | E7: =SUM(E2:E6)-'Revenue breakdown'!E3 -> 0 | F7: =SUM(F2:F6)-'Revenue breakdown'!F3 -> 0 | G7: =SUM(G2:G6)-'Revenue breakdown'!G3 -> 0 | H7: =SUM(H2:H6)-'Revenue breakdown'!H3 -> 0 | I7: =SUM(I2:I6)-'Revenue breakdown'!I3 -> 0 | ... L7: =SUM(L2:L6)-'Revenue breakdown'!L3 -> 0
A46: Active students | B46: 39833 | C46: 52005 | D46: 74313 | E46: 108100 | F46: 145000 | G46: 174000 | H46: 208800 | I46: 250560 | J46: 300672 | K46: 360806.4 | L46: 432967.68
A47: Average tuition fee per pax (vnd'000) | B47: ='Revenue breakdown'!B31/10^3 -> 38966.429 | C47: ='Revenue breakdown'!C31/10^3 -> 29977.887 | D47: ='Revenue breakdown'!D31/10^3 -> 30075.492 | E47: ='Revenue breakdown'!E31/10^3 -> 32534.69 | F47: ='Revenue breakdown'!F31/10^3 -> 37013.972 | G47: ='Revenue breakdown'!G31/10^3 -> 38587.499 | H47: ='Revenue breakdown'!H31/10^3 -> 39359.249 | I47: ='Revenue breakdown'!I31/10^3 -> 40146.434 | ... L47: ='Revenue breakdown'!L31/10^3 -> 42603.717
A48: % growth Active students | C48: 0.30557578 | D48: 0.42895875 | E48: 0.454658 | F48: 0.3413506 | G48: 0.2 | H48: 0.2 | I48: 0.2 | J48: 0.2 | K48: 0.2 | L48: 0.2
A49: % growth Average tuition fee | C49: -0.230674 | D49: 0.003255892 | E49: 0.081767528 | F49: 0.1376771 | G49: 0.04251171 | H49: 0.02 | I49: 0.02 | J49: 0.02 | K49: 0.02 | L49: 0.02
