Workbook

Sheet FPT Digital Retail JSC | Cash F
A1: FPT Digital Retail JSC | Cash Flow 11-Oct-2023 12:01
A3: Cash Flow
A4: Industry - Annual Standardised in Millions of Vietnamese Dong
B5: 2016 | C5: 2017 | D5: 2018 | E5: 2019 | F5: 2019 | G5: 2020 | H5: 2021 | I5: 2022 | J5: 2023F | K5: 2024F | L5: 2025F | M5: 2026F | N5: 2027F | O5: 2028F
A6: Earnings Quality Score | B6: N/A | C6: N/A | D6: 2 | E6: -- | F6: 17 | G6: 89 | H6: 10 | I6: 12
A7: Period End Date | B7: 31-Dec-2016 | C7: 31-Dec-2017 | D7: 31-Dec-2018 | E7: 31-Dec-2019 | F7: 31-Dec-2019 | G7: 31-Dec-2020 | H7: 31-Dec-2021 | I7: 31-Dec-2022 | J7: 31-Dec-2018 | K7: 31-Dec-2019 | L7: 31-Dec-2019 | M7: 31-Dec-2020 | N7: 31-Dec-2021 | O7: 31-Dec-2022
A8: Period Length | B8: 12 Months | C8: 12 Months | D8: 12 Months | E8: 12 Months | F8: 12 Months | G8: 12 Months | H8: 12 Months | I8: 12 Months | J8: 12 Months | K8: 12 Months | L8: 12 Months | M8: 12 Months | N8: 12 Months | O8: 12 Months
A9: Update Type | B9: Updated | C9: Updated | D9: Updated | E9: Updated | F9: Restated | G9: Updated | H9: Updated | I9: Updated | J9: Updated | K9: Updated | L9: Restated | M9: Updated | N9: Updated | O9: Updated
A10: Statement Date | B10: 31-Dec-2017 | C10: 31-Dec-2017 | D10: 31-Dec-2018 | E10: 31-Dec-2019 | F10: 31-Dec-2020 | G10: 31-Dec-2020 | H10: 31-Dec-2021 | I10: 31-Dec-2022 | J10: 31-Dec-2018 | K10: 31-Dec-2019 | L10: 31-Dec-2020 | M10: 31-Dec-2020 | N10: 31-Dec-2021 | O10: 31-Dec-2022
A11: Reporting Unit | B11: Thousands | C11: Thousands | D11: Thousands | E11: Thousands | F11: Thousands | G11: Thousands | H11: Thousands | I11: Thousands | J11: Thousands | K11: Thousands | L11: Thousands | M11: Thousands | N11: Thousands | O11: Thousands
A12: Update Date | B12: 30-Oct-2020 | C12: 23-Nov-2022 | D12: 06-Jun-2022 | E12: 06-Jun-2023 | F12: 06-Jun-2023 | G12: 06-Jun-2023 | H12: 06-Jun-2023 | I12: 08-Jun-2023 | J12: 06-Jun-2022 | K12: 06-Jun-2023 | L12: 06-Jun-2023 | M12: 06-Jun-2023 | N12: 06-Jun-2023 | O12: 08-Jun-2023
A13: Reporting Currency | B13: Vietnamese Dong | C13: Vietnamese Dong | D13: Vietnamese Dong | E13: Vietnamese Dong | F13: Vietnamese Dong | G13: Vietnamese Dong | H13: Vietnamese Dong | I13: Vietnamese Dong | J13: Vietnamese Dong | K13: Vietnamese Dong | L13: Vietnamese Dong | M13: Vietnamese Dong | N13: Vietnamese Dong | O13: Vietnamese Dong
A14: Source | B14: ARS | C14: ARS | D14: ARS | E14: ARS | F14: ARS | G14: ARS | H14: ARS | I14: ARS | J14: ARS | K14: ARS | L14: ARS | M14: ARS | N14: ARS | O14: ARS
A15: Source Date | B15: 27-Apr-2018 | C15: 27-Apr-2018 | D15: 16-Apr-2019 | E15: 31-Mar-2020 | F15: 31-Mar-2021 | G15: 31-Mar-2021 | H15: 14-Mar-2022 | I15: 27-Mar-2023 | J15: 16-Apr-2019 | K15: 31-Mar-2020 | L15: 31-Mar-2021 | M15: 31-Mar-2021 | N15: 14-Mar-2022 | O15: 27-Mar-2023
A16: Original Announcement Date | B16: 10-Apr-2018 03:48 | C16: 27-Apr-2018 05:00 | D16: 21-Jan-2019 11:01 | E16: 22-Jan-2020 14:59 | F16: 01-Feb-2021 06:43 | G16: 01-Feb-2021 06:43 | H16: 07-Feb-2022 15:18 | I16: 31-Jan-2023 20:37 | J16: 21-Jan-2019 11:01 | K16: 22-Jan-2020 14:59 | L16: 01-Feb-2021 06:43 | M16: 01-Feb-2021 06:43 | N16: 07-Feb-2022 15:18 | O16: 31-Jan-2023 20:37
A17: Complete Statement | B17: Complete | C17: Complete | D17: Complete | E17: Complete | F17: Complete | G17: Complete | H17: Complete | I17: Complete | J17: Complete | K17: Complete | L17: Complete | M17: Complete | N17: Complete | O17: Complete
A18: Flash Update | B18: No | C18: No | D18: No | E18: No | F18: No | G18: No | H18: No | I18: No | J18: No | K18: No | L18: No | M18: No | N18: No | O18: No
... A22: Accounting Standard | B22: Vietnamese Accounting Standards | C22: Vietnamese Accounting Standards | D22: Vietnamese Accounting Standards | E22: Vietnamese Accounting Standards | F22: Vietnamese Accounting Standards | G22: Vietnamese Accounting Standards | H22: Vietnamese Accounting Standards | I22: Vietnamese Accounting Standards | J22: Vietnamese Accounting Standards | K22: Vietnamese Accounting Standards | L22: Vietnamese Accounting Standards | M22: Vietnamese Accounting Standards | N22: Vietnamese Accounting Standards | O22: Vietnamese Accounting Standards
A23: Cash Flow-Operating Activities (VND Millions)
A24: Net Income/Starting Line | B24: 259383 | C24: 363074 | D24: 434775 | E24: 278003 | F24: 278003 | G24: 28427 | H24: 554140 | I24: 485623
A25: Depreciation/Depletion | B25: 1705 | C25: 498 | D25: 781 | E25: 837 | F25: 837 | G25: 1372 | H25: 3811 | I25: 115286
A26: Depreciation | B26: 1705 | C26: 498 | D26: 781 | E26: 837 | F26: 837 | G26: 1372 | H26: 3811 | I26: 115286
A27: Amortization | B27: -- | C27: 586 | D27: -- | E27: -- | F27: -- | G27: -- | H27: -- | I27: --
A28: Amortization of Intangibles | B28: -- | C28: 586 | D28: -- | E28: -- | F28: -- | G28: -- | H28: -- | I28: --
A29: Deferred Taxes | B29: -- | C29: -- | D29: -- | E29: -- | F29: -- | G29: -- | H29: -- | I29: --
A30: Non-Cash Items | B30: 36188 | C30: 19667 | D30: 86821 | E30: 91276 | F30: 91276 | G30: 92129 | H30: -60641 | I30: 79146
A31: Unusual Items | B31: -54495 | C31: -34483 | D31: -20946 | E31: -61193 | F31: -61193 | G31: -55871 | H31: -169344 | I31: -147854
A32: Other Non-Cash Items | B32: 90683 | C32: 54150 | D32: 107767 | E32: 152469 | F32: 152469 | G32: 148000 | H32: 108703 | I32: 227000
A33: Changes in Working Capital | B33: -56446 | C33: -204966 | D33: -1909113 | E33: -478312 | F33: -495767 | G33: 1396404 | H33: -1971663 | I33: -2187748 | J33: =I33*(1+J34) -> -1144435.4 | K33: =J33*(1+K34) -> -676930.99 | L33: =K33*(1+L34) -> -394718.79 | M33: =L33*(1+M34) -> -227153.47 | N33: =M33*(1+N34) -> -141451.99 | O33: =N33*(1+O34) -> -85123.534
D34: =D33/('FPT Digital Retail JSC | Income'!E23-'FPT Digital Retail JSC | Income'!D23) -> -0.8872085 | E34: =E33/('FPT Digital Retail JSC | Income'!F23-'FPT Digital Retail JSC | Income'!E23) -> -0.35811848 | F34: =F33/('FPT Digital Retail JSC | Income'!F23-'FPT Digital Retail JSC | Income'!E23) -> -0.37118727 | G34: =G33/('FPT Digital Retail JSC | Income'!G23-'FPT Digital Retail JSC | Income'!F23) -> -0.70792069 | H34: =H33/('FPT Digital Retail JSC | Income'!H23-'FPT Digital Retail JSC | Income'!G23) -> -0.25169489 | I34: =I33/('FPT Digital Retail JSC | Income'!I23-'FPT Digital Retail JSC | Income'!H23) -> -0.28520319 | J34: =AVERAGE(D34:I34) -> -0.47688884 | K34: =AVERAGE(E34:J34) -> -0.40850223 | L34: =AVERAGE(F34:K34) -> -0.41689952 | M34: =AVERAGE(G34:L34) -> -0.42451822 | N34: =AVERAGE(H34:M34) -> -0.37728448 | O34: =AVERAGE(I34:N34) -> -0.39821608
A35: Changes in Working Capital | B35: -56446 | C35: -204966 | D35: =SUM(D36,D39,D40,D42) -> -1709917 | E35: =SUM(E36,E39,E40,E42) -> -259588 | F35: =SUM(F36,F39,F40,F42) -> 1279781 | G35: =SUM(G36,G39,G40,G42) -> -1552472 | H35: =SUM(H36,H39,H40,H42) -> -3292417 | I35: =SUM(I36,I39,I40,I42) -> -3172437 | J35: =SUM(J36,J39,J40,J42) -> -1856662.9 | K35: =SUM(K36,K39,K40,K42) -> -1158338.2 | ... O35: =SUM(O36,O39,O40,O42) -> 8964987.8
A36: Accounts Receivable | B36: -289037 | C36: -432257 | D36: -60063 | E36: 131186 | F36: 113731 | G36: -79330 | H36: 51734 | I36: -93023 | J36: =I36*(1+J38) -> -90625.774 | K36: =J36*(1+K38) -> -87505.502 | L36: =K36*(1+L38) -> -84879.653 | M36: =L36*(1+M38) -> -83112.702 | N36: =M36*(1+N38) -> -81651.265 | O36: =N36*(1+O38) -> -80066.108
A37: Accounts Receivable | D37: ='FPT Digital Retail JSC | BS'!D27-'FPT Digital Retail JSC | BS'!C27 -> -74823 | E37: ='FPT Digital Retail JSC | BS'!E27-'FPT Digital Retail JSC | BS'!D27 -> 40076 | F37: ='FPT Digital Retail JSC | BS'!E27-'FPT Digital Retail JSC | BS'!D27 -> 40076 | G37: ='FPT Digital Retail JSC | BS'!F27-'FPT Digital Retail JSC | BS'!E27 -> -145516 | H37: ='FPT Digital Retail JSC | BS'!G27-'FPT Digital Retail JSC | BS'!F27 -> -41622 | I37: ='FPT Digital Retail JSC | BS'!H27-'FPT Digital Retail JSC | BS'!G27 -> 9502 | J37: ='FPT Digital Retail JSC | BS'!H27-'FPT Digital Retail JSC | BS'!I27 -> -253885.41 | K37: ='FPT Digital Retail JSC | BS'!I27-'FPT Digital Retail JSC | BS'!J27 -> 21535.212 | L37: ='FPT Digital Retail JSC | BS'!J27-'FPT Digital Retail JSC | BS'!K27 -> 46423.236 | M37: ='FPT Digital Retail JSC | BS'!K27-'FPT Digital Retail JSC | BS'!L27 -> -5331.9931 | N37: ='FPT Digital Retail JSC | BS'!L27-'FPT Digital Retail JSC | BS'!M27 -> -43604.398 | O37: ='FPT Digital Retail JSC | BS'!M27-'FPT Digital Retail JSC | BS'!N27 -> -65726.922
A38: % sales change | D38: =-D36/('FPT Digital Retail JSC | Income'!D23-'FPT Digital Retail JSC | Income'!C23) -> 0.026189957 | E38: =-E36/('FPT Digital Retail JSC | Income'!E23-'FPT Digital Retail JSC | Income'!D23) -> -0.060965136 | F38: =-F36/('FPT Digital Retail JSC | Income'!F23-'FPT Digital Retail JSC | Income'!E23) -> -0.085151895 | G38: =-G36/('FPT Digital Retail JSC | Income'!G23-'FPT Digital Retail JSC | Income'!F23) -> -0.040217121 | H38: =-H36/('FPT Digital Retail JSC | Income'!H23-'FPT Digital Retail JSC | Income'!G23) -> -0.0066041628 | I38: =-I36/('FPT Digital Retail JSC | Income'!I23-'FPT Digital Retail JSC | Income'!H23) -> 0.012126834 | J38: =AVERAGE(D38:I38) -> -0.025770254 | K38: =AVERAGE(E38:J38) -> -0.034430289 | L38: =AVERAGE(F38:K38) -> -0.030007815 | M38: =AVERAGE(G38:L38) -> -0.020817135 | N38: =AVERAGE(H38:M38) -> -0.017583804 | O38: =AVERAGE(I38:N38) -> -0.019413744
A39: Inventories | B39: -756654 | C39: 256198 | D39: ='FPT Digital Retail JSC | BS'!C37-'FPT Digital Retail JSC | BS'!D37 -> -782741 | E39: ='FPT Digital Retail JSC | BS'!D37-'FPT Digital Retail JSC | BS'!E37 -> -877323 | F39: ='FPT Digital Retail JSC | BS'!D37-'FPT Digital Retail JSC | BS'!F37 -> 679501 | G39: ='FPT Digital Retail JSC | BS'!E37-'FPT Digital Retail JSC | BS'!G37 -> -1546817 | H39: ='FPT Digital Retail JSC | BS'!F37-'FPT Digital Retail JSC | BS'!H37 -> -4657110 | I39: ='FPT Digital Retail JSC | BS'!G37-'FPT Digital Retail JSC | BS'!I37 -> -2889466 | J39: ='FPT Digital Retail JSC | BS'!H37-'FPT Digital Retail JSC | BS'!J37 -> -1740389.7 | K39: ='FPT Digital Retail JSC | BS'!I37-'FPT Digital Retail JSC | BS'!K37 -> -1041312.9 | L39: ='FPT Digital Retail JSC | BS'!J37-'FPT Digital Retail JSC | BS'!L37 -> -798277.72 | M39: ='FPT Digital Retail JSC | BS'!K37-'FPT Digital Retail JSC | BS'!M37 -> -330881.28 | ... O39: ='FPT Digital Retail JSC | BS'!M37-'FPT Digital Retail JSC | BS'!O37 -> 9192019.2
A40: Prepaid Expenses | B40: -9167 | C40: -9282 | D40: -17223 | E40: -68023 | F40: -68023 | G40: 8228 | H40: -40582 | I40: -226194 | J40: =AVERAGE(D40:I40) -> -68636.167 | K40: =AVERAGE(E40:I40) -> -78918.8 | L40: =AVERAGE(F40:I40) -> -81642.75 | M40: =AVERAGE(G40:I40) -> -86182.667 | N40: =AVERAGE(H40:I40) -> -133388 | O40: =AVERAGE(I40:I40) -> -226194
A41: Accounts Payable | B41: 1117290 | C41: 126774 | D41: ='FPT Digital Retail JSC | BS'!D75 -> -793137 | E41: ='FPT Digital Retail JSC | BS'!E75 -> 581630 | F41: ='FPT Digital Retail JSC | BS'!F75 -> -72732 | G41: ='FPT Digital Retail JSC | BS'!G75 -> 1120953 | H41: ='FPT Digital Retail JSC | BS'!H75 -> -28387 | I41: ='FPT Digital Retail JSC | BS'!I75 -> 896119.51 | J41: ='FPT Digital Retail JSC | BS'!I75 -> 896119.51 | K41: ='FPT Digital Retail JSC | BS'!J75 -> 26129.336 | L41: ='FPT Digital Retail JSC | BS'!K75 -> 491761.97 | M41: ='FPT Digital Retail JSC | BS'!L75 -> 362047.52 | N41: ='FPT Digital Retail JSC | BS'!M75 -> 292753 | O41: ='FPT Digital Retail JSC | BS'!N75 -> 202628.53
A42: Accounts Payable | B42: 1117290 | C42: 126774 | D42: -849890 | E42: 554572 | F42: 554572 | G42: 65447 | H42: 1353541 | I42: 36246 | J42: =I42*(1+J43) -> 42988.746 | K42: =J42*(1+K43) -> 49399.027 | L42: =K42*(1+L43) -> 56765.18 | M42: =L42*(1+M43) -> 62712.202 | N42: =M42*(1+N43) -> 70724.066 | O42: =N42*(1+O43) -> 79228.688
A43: %/ sales change | D43: =-D42/('FPT Digital Retail JSC | Income'!D23-'FPT Digital Retail JSC | Income'!C23) -> 0.37058726 | F43: =F42/('Revenue breakdown'!C3-'Revenue breakdown'!B3) -> 0.41521535 | G43: =G42/('Revenue breakdown'!D3-'Revenue breakdown'!C3) -> -0.033178998 | H43: =H42/('Revenue breakdown'!E3-'Revenue breakdown'!D3) -> 0.17278782 | I43: =I42/('Revenue breakdown'!F3-'Revenue breakdown'!E3) -> 0.004725167 | J43: =AVERAGE(D43:I43) -> 0.18602732 | K43: =AVERAGE(E43:J43) -> 0.14911533 | L43: =AVERAGE(F43:K43) -> 0.14911533 | M43: =AVERAGE(G43:L43) -> 0.10476533 | N43: =AVERAGE(H43:M43) -> 0.12775605 | O43: =AVERAGE(I43:N43) -> 0.12025075
A44: Other Operating Cash Flow | B44: -118877 | C44: -146398 | D44: -191702 | E44: -216538 | F44: -216538 | G44: -143899 | H44: -213516 | I44: -355188 | J44: =AVERAGE(D44:I44) -> -222896.83 | K44: =AVERAGE(E44:J44) -> -228095.97 | L44: =AVERAGE(F44:K44) -> -230022.3 | M44: =AVERAGE(G44:L44) -> -232269.68 | N44: =AVERAGE(H44:M44) -> -246998.13 | O44: =AVERAGE(I44:N44) -> -252578.49
...

Sheet FPT Digital Retail JSC | BS
A1: FPT Digital Retail JSC | Balance Sheet 11-Oct-2023 12:01
A3: Balance Sheet | E3: =E32-D32 -> 92247
A4: Industry - Annual Standardised in Millions of Vietnamese Dong
B5: 2016 | C5: 2017 | D5: 2018 | E5: 2019 | F5: 2020 | G5: 2021 | H5: 2022 | I5: 2023F | J5: 2024F | K5: 2025F | L5: 2026F | M5: 2027F | N5: 2028F
A6: Earnings Quality Score | B6: N/A | C6: N/A | D6: 2 | E6: 17 | F6: 89 | G6: 10 | H6: 12
A7: Period End Date | B7: 31-Dec-2016 | C7: 31-Dec-2017 | D7: 31-Dec-2018 | E7: 31-Dec-2019 | F7: 31-Dec-2020 | G7: 31-Dec-2021 | H7: 31-Dec-2022 | I7: 31-Dec-2018 | J7: 31-Dec-2019 | K7: 31-Dec-2019 | L7: 31-Dec-2020 | M7: 31-Dec-2021 | N7: 31-Dec-2022
A8: Update Type | B8: Updated | C8: Updated | D8: Updated | E8: Updated | F8: Updated | G8: Updated | H8: Updated | I8: Updated | J8: Updated | K8: Restated | L8: Updated | M8: Updated | N8: Updated
A9: Statement Date | B9: 31-Dec-2017 | C9: 31-Dec-2017 | D9: 31-Dec-2018 | E9: 31-Dec-2019 | F9: 31-Dec-2020 | G9: 31-Dec-2021 | H9: 31-Dec-2022 | I9: 31-Dec-2018 | J9: 31-Dec-2019 | K9: 31-Dec-2020 | L9: 31-Dec-2020 | M9: 31-Dec-2021 | N9: 31-Dec-2022
A10: Reporting Unit | B10: Thousands | C10: Thousands | D10: Thousands | E10: Thousands | F10: Thousands | G10: Thousands | H10: Thousands | I10: Thousands | J10: Thousands | K10: Thousands | L10: Thousands | M10: Thousands | N10: Thousands
A11: Update Date | B11: 06-Jun-2023 | C11: 06-Jun-2023 | D11: 06-Jun-2023 | E11: 06-Jun-2023 | F11: 06-Jun-2023 | G11: 06-Jun-2023 | H11: 08-Jun-2023 | I11: 06-Jun-2022 | J11: 06-Jun-2023 | K11: 06-Jun-2023 | L11: 06-Jun-2023 | M11: 06-Jun-2023 | N11: 08-Jun-2023
A12: Reporting Currency | B12: Vietnamese Dong | C12: Vietnamese Dong | D12: Vietnamese Dong | E12: Vietnamese Dong | F12: Vietnamese Dong | G12: Vietnamese Dong | H12: Vietnamese Dong | I12: Vietnamese Dong | J12: Vietnamese Dong | K12: Vietnamese Dong | L12: Vietnamese Dong | M12: Vietnamese Dong | N12: Vietnamese Dong
A13: Source | B13: ARS | C13: ARS | D13: ARS | E13: ARS | F13: ARS | G13: ARS | H13: ARS | I13: ARS | J13: ARS | K13: ARS | L13: ARS | M13: ARS | N13: ARS
A14: Source Date | B14: 27-Apr-2018 | C14: 27-Apr-2018 | D14: 16-Apr-2019 | E14: 31-Mar-2020 | F14: 31-Mar-2021 | G14: 14-Mar-2022 | H14: 27-Mar-2023 | I14: 16-Apr-2019 | J14: 31-Mar-2020 | K14: 31-Mar-2021 | L14: 31-Mar-2021 | M14: 14-Mar-2022 | N14: 27-Mar-2023
A15: Original Announcement Date | B15: 10-Apr-2018 03:48 | C15: 27-Apr-2018 05:00 | D15: 21-Jan-2019 11:01 | E15: 22-Jan-2020 14:59 | F15: 01-Feb-2021 06:43 | G15: 07-Feb-2022 15:18 | H15: 31-Jan-2023 20:37 | I15: 21-Jan-2019 11:01 | J15: 22-Jan-2020 14:59 | K15: 01-Feb-2021 06:43 | L15: 01-Feb-2021 06:43 | M15: 07-Feb-2022 15:18 | N15: 31-Jan-2023 20:37
A16: Complete Statement | B16: Complete | C16: Complete | D16: Complete | E16: Complete | F16: Complete | G16: Complete | H16: Complete | I16: Complete | J16: Complete | K16: Complete | L16: Complete | M16: Complete | N16: Complete
A17: Flash Update | B17: No | C17: No | D17: No | E17: No | F17: No | G17: No | H17: No | I17: No | J17: No | K17: No | L17: No | M17: No | N17: No
A18: Consolidated | B18: Yes | C18: Yes | D18: Yes | E18: Yes | F18: Yes | G18: Yes | H18: Yes | I18: Yes | J18: Yes | K18: Yes | L18: Yes | M18: Yes | N18: Yes
... A21: Accounting Standard | B21: Vietnamese Accounting Standards | C21: Vietnamese Accounting Standards | D21: Vietnamese Accounting Standards | E21: Vietnamese Accounting Standards | F21: Vietnamese Accounting Standards | G21: Vietnamese Accounting Standards | H21: Vietnamese Accounting Standards | I21: Vietnamese Accounting Standards | J21: Vietnamese Accounting Standards | K21: Vietnamese Accounting Standards | L21: Vietnamese Accounting Standards | M21: Vietnamese Accounting Standards | N21: Vietnamese Accounting Standards
A22: Assets (VND Millions)
A23: Cash and Short Term Investments | B23: 1457807 | C23: 638076 | D23: 952518 | E23: 1364293 | F23: 1489663 | G23: 2925710 | H23: 1864556
A24: Cash | B24: 409709 | C24: 567217 | D24: 855378 | E24: 415979 | F24: 551504 | G24: 679939 | H24: 450488
A25: Cash & Equivalents | B25: 1047798 | C25: 70859 | D25: 93000 | E25: 453671 | F25: 150000 | G25: 425271 | H25: 295068
A26: Short Term Investments | B26: 300 | C26: 0 | D26: 4140 | E26: 494643 | F26: 788159 | G26: 1820500 | H26: 1119000
A27: Accounts Receivable - Trade, Net | B27: 115139 | C27: 294862 | D27: 220039 | E27: 260115 | F27: 114599 | G27: 72977 | H27: 82479 | I27: =I54*'Revenue breakdown'!G3 -> 336364.41 | J27: =J54*'Revenue breakdown'!H3 -> 314829.2 | K27: =K54*'Revenue breakdown'!I3 -> 268405.96 | L27: =L54*'Revenue breakdown'!J3 -> 273737.96 | M27: =M54*'Revenue breakdown'!K3 -> 317342.36 | N27: =N54*'Revenue breakdown'!L3 -> 383069.28
A28: Accounts Receivable - Trade, Gross | B28: 119330 | C28: 305662 | D28: 237824 | E28: 294575 | F28: 172585 | G28: 80725 | H28: 89623
A29: Provision for Doubtful Accounts | B29: -4191 | C29: -10800 | D29: -17785 | E29: -34459 | F29: -57986 | G29: -7749 | H29: -7143
A30: Total Receivables (excl. note receivables) | D30: =D32-D35 -> 997840 | E30: =E32-E35 -> 888087 | F30: =F32-F35 -> 545692 | G30: =G32-G35 -> 477246 | H30: =H32-H35 -> 603715 | I30: =I31*'Revenue breakdown'!G3 -> 1512827.6 | J30: =J31*'Revenue breakdown'!H3 -> 1533930.6 | K30: =K31*'Revenue breakdown'!I3 -> 1654138 | L30: =L31*'Revenue breakdown'!J3 -> 1792479.9 | M30: =M31*'Revenue breakdown'!K3 -> 1913717.1 | N30: =N31*'Revenue breakdown'!L3 -> 2078532.6
A31: %rev | D31: =D30/'Revenue breakdown'!B3 -> 0.065225399 | E31: =E30/'Revenue breakdown'!C3 -> 0.053389993 | F31: =F30/'Revenue breakdown'!D3 -> 0.037219595 | G31: =G30/'Revenue breakdown'!E3 -> 0.021215685 | H31: =H30/'Revenue breakdown'!F3 -> 0.020013226 | I31: =AVERAGE(D31:H31) -> 0.039412779 | J31: =MEDIAN(E31:I31) -> 0.037219595 | K31: =MEDIAN(F31:J31) -> 0.037219595 | L31: =MEDIAN(G31:K31) -> 0.037219595 | M31: =MEDIAN(H31:L31) -> 0.037219595 | N31: =MEDIAN(I31:M31) -> 0.037219595
A32: Total Receivables, Net | B32: 852723 | C32: 1026478 | D32: 1118199 | E32: 1210446 | F32: 1430692 | G32: 2037246 | H32: 643715 | I32: =I33*'Revenue breakdown'!G3 -> 2667554.2 | J32: =J33*'Revenue breakdown'!H3 -> 2899346.9 | K32: =K33*'Revenue breakdown'!I3 -> 3105052.5 | L32: =L33*'Revenue breakdown'!J3 -> 3097785.2 | M32: =M33*'Revenue breakdown'!K3 -> 3037460.4 | N32: =N33*'Revenue breakdown'!L3 -> 3720529.4
A33: %rev | D33: =D30/'Revenue breakdown'!B3 -> 0.065225399 | E33: =E32/'Revenue breakdown'!C3 -> 0.072769563 | F33: =F32/'Revenue breakdown'!D3 -> 0.09758211 | G33: =G32/'Revenue breakdown'!E3 -> 0.090564549 | H33: =H32/'Revenue breakdown'!F3 -> 0.021339231 | I33: =AVERAGE(D33:H33) -> 0.06949617 | J33: =AVERAGE(E33:I33) -> 0.070350325 | K33: =AVERAGE(F33:J33) -> 0.069866477 | L33: =AVERAGE(G33:K33) -> 0.06432335 | M33: =AVERAGE(H33:L33) -> 0.059075111 | N33: =AVERAGE(I33:M33) -> 0.066622287
A34: %growth | D34: =D32/C32-1 -> 0.089355057 | E34: =E32/D32-1 -> 0.082496049 | F34: =F32/E32-1 -> 0.18195442 | G34: =G32/F32-1 -> 0.42395848 | H34: =H32/G32-1 -> -0.68402687
A35: Notes Receivable - Short Term | B35: 280150 | C35: 0 | D35: 120359 | E35: 322359 | F35: 885000 | G35: 1560000 | H35: 40000
A36: Receivables - Other | B36: 457434 | C36: 731616 | D36: 777800 | E36: 627971 | F36: 431093 | G36: 404269 | H36: 521235
A37: Total Inventory | B37: 1948265 | C37: 1723478 | D37: 2506219 | E37: 3383542 | F37: 1826718 | G37: 4930359 | H37: 6483828 | I37: =SUM(I40,I43) -> 7819825 | J37: =SUM(J40,J43) -> 8224217.7 | K37: =SUM(K40,K43) -> 8861137.9 | L37: =SUM(L40,L43) -> 9022495.4 | M37: =SUM(M40,M43) -> 9192019.2 | N37: =SUM(N40,N43) -> 9649471.5
A38: growth | E38: =E37/D37-1 -> 0.35005839 | F38: =F37/E37-1 -> -0.46011665 | G38: =G37/F37-1 -> 1.6990258 | H38: =H37/G37-1 -> 0.31508233
A39: weighted | D39: =D37/'Revenue breakdown'!B3 -> 0.16382299 | E39: =E37/'Revenue breakdown'!C3 -> 0.2034117 | F39: =F37/'Revenue breakdown'!D3 -> 0.12459355 | G39: =G37/'Revenue breakdown'!E3 -> 0.21917615 | H39: =H37/'Revenue breakdown'!F3 -> 0.21493969 | I39: =I37/'Revenue breakdown'!G3 -> 0.20372516 | J39: =J37/'Revenue breakdown'!H3 -> 0.19955404 | K39: =K37/'Revenue breakdown'!I3 -> 0.19938358 | ... N39: =N37/'Revenue breakdown'!L3 -> 0.17278989
A40: FPT shop inv | D40: =D37*'Revenue breakdown'!B8 -> 2449700.1 | E40: =E37*'Revenue breakdown'!C8 -> 3279642.6 | F40: =F37*'Revenue breakdown'!D8 -> 1678988.7 | G40: =G37*'Revenue breakdown'!E8 -> 4067489.2 | H40: =H37*'Revenue breakdown'!F8 -> 4446850.5 | I40: =I41*'Revenue breakdown'!G9 -> 5144009.4 | J40: =J41*'Revenue breakdown'!H9 -> 5309698 | K40: =K41*'Revenue breakdown'!I9 -> 5676726 | L40: =L41*'Revenue breakdown'!J9 -> 5801236.4 | M40: =M41*'Revenue breakdown'!K9 -> 6048683.4 | N40: =N41*'Revenue breakdown'!L9 -> 6369454.7
A41: FPT shop inv per store | D41: =D40/'Revenue breakdown'!B9 -> 4596.0602 | E41: =E40/'Revenue breakdown'!C9 -> 5530.5945 | F41: =F40/'Revenue breakdown'!D9 -> 2821.8297 | G41: =G40/'Revenue breakdown'!E9 -> 6286.6912 | H41: =H40/'Revenue breakdown'!F9 -> 5657.5707 | I41: =H41*(1+I42) -> 5949.6767 | J41: =I41*(1+J42) -> 5805.5731 | K41: =J41*(1+K42) -> 5885.1402 | L41: =K41*(1+L42) -> 5854.1987 | M41: =L41*(1+M42) -> 5878.9261 | N41: =M41*(1+N42) -> 5875.8876
A42: growth | E42: =(E41-D41)/D41 -> 0.2033338 | F42: =(F41-E41)/E41 -> -0.48977824 | G42: =(G41-F41)/F41 -> 1.2278776 | H42: =(H41-G41)/G41 -> -0.10007181 | I42: =MEDIAN(E42:H42) -> 0.051630995 | J42: =MEDIAN(F42:I42) -> -0.024220406 | K42: =MEDIAN(G42:J42) -> 0.013705294 | L42: =MEDIAN(H42:K42) -> -0.005257556 | M42: =MEDIAN(I42:L42) -> 0.0042238692 | N42: =MEDIAN(J42:M42) -> -0.0005168434
A43: Long Chau shop inv | D43: =D37*'Revenue breakdown'!B15 -> 56518.932 | E43: =E37*'Revenue breakdown'!C15 -> 103899.24 | F43: =F37*'Revenue breakdown'!D15 -> 148370.98 | G43: =G37*'Revenue breakdown'!E15 -> 871704.76 | H43: =H37*'Revenue breakdown'!F15 -> 2062548.8 | I43: =I44*'Revenue breakdown'!G16 -> 2675815.7 | J43: =J44*'Revenue breakdown'!H16 -> 2914519.7 | K43: =K44*'Revenue breakdown'!I16 -> 3184411.9 | L43: =L44*'Revenue breakdown'!J16 -> 3221259 | M43: =M44*'Revenue breakdown'!K16 -> 3143335.8 | N43: =N44*'Revenue breakdown'!L16 -> 3280016.8
...

Sheet FPT Digital Retail JSC | Income
A1: FPT Digital Retail JSC | Income Statement 11-Oct-2023 12:01
A3: Income Statement
A4: Industry - Annual Standardised in Millions of Vietnamese Dong
C5: 2016 | D5: 2017 | E5: 2018 | F5: 2019 | G5: 2020 | H5: 2021 | I5: 2022 | J5: 2023F | K5: 2024F | L5: 2025F | M5: 2026F | N5: 2027F | O5: 2028F
A6: Earnings Quality Score | C6: N/A | D6: N/A | E6: 2 | F6: 17 | G6: 89 | H6: 10 | I6: 12
A7: Period End Date | C7: 31-Dec-2016 | D7: 31-Dec-2017 | E7: 31-Dec-2018 | F7: 31-Dec-2019 | G7: 31-Dec-2020 | H7: 31-Dec-2021 | I7: 31-Dec-2022 | J7: 31-Dec-2018 | K7: 31-Dec-2019 | L7: 31-Dec-2019 | M7: 31-Dec-2020 | N7: 31-Dec-2021 | O7: 31-Dec-2022
A8: Period Length | C8: 12 Months | D8: 12 Months | E8: 12 Months | F8: 12 Months | G8: 12 Months | H8: 12 Months | I8: 12 Months | J8: Updated | K8: Updated | L8: Restated | M8: Updated | N8: Updated | O8: Updated
A9: Update Type | C9: Updated | D9: Updated | E9: Updated | F9: Updated | G9: Updated | H9: Updated | I9: Updated | J9: 31-Dec-2018 | K9: 31-Dec-2019 | L9: 31-Dec-2020 | M9: 31-Dec-2020 | N9: 31-Dec-2021 | O9: 31-Dec-2022
A10: Statement Date | C10: 31-Dec-2017 | D10: 31-Dec-2017 | E10: 31-Dec-2018 | F10: 31-Dec-2019 | G10: 31-Dec-2020 | H10: 31-Dec-2021 | I10: 31-Dec-2022 | J10: Thousands | K10: Thousands | L10: Thousands | M10: Thousands | N10: Thousands | O10: Thousands
A11: Reporting Unit | C11: Thousands | D11: Thousands | E11: Thousands | F11: Thousands | G11: Thousands | H11: Thousands | I11: Thousands | J11: 06-Jun-2022 | K11: 06-Jun-2023 | L11: 06-Jun-2023 | M11: 06-Jun-2023 | N11: 06-Jun-2023 | O11: 08-Jun-2023
A12: Update Date | C12: 06-Jun-2023 | D12: 06-Jun-2023 | E12: 06-Jun-2023 | F12: 06-Jun-2023 | G12: 06-Jun-2023 | H12: 06-Jun-2023 | I12: 08-Jun-2023 | J12: Vietnamese Dong | K12: Vietnamese Dong | L12: Vietnamese Dong | M12: Vietnamese Dong | N12: Vietnamese Dong | O12: Vietnamese Dong
A13: Reporting Currency | C13: Vietnamese Dong | D13: Vietnamese Dong | E13: Vietnamese Dong | F13: Vietnamese Dong | G13: Vietnamese Dong | H13: Vietnamese Dong | I13: Vietnamese Dong | J13: ARS | K13: ARS | L13: ARS | M13: ARS | N13: ARS | O13: ARS
A14: Source | C14: ARS | D14: ARS | E14: ARS | F14: ARS | G14: ARS | H14: ARS | I14: ARS | J14: 16-Apr-2019 | K14: 31-Mar-2020 | L14: 31-Mar-2021 | M14: 31-Mar-2021 | N14: 14-Mar-2022 | O14: 27-Mar-2023
A15: Source Date | C15: 27-Apr-2018 | D15: 27-Apr-2018 | E15: 16-Apr-2019 | F15: 31-Mar-2020 | G15: 31-Mar-2021 | H15: 14-Mar-2022 | I15: 27-Mar-2023 | J15: 21-Jan-2019 11:01 | K15: 22-Jan-2020 14:59 | L15: 01-Feb-2021 06:43 | M15: 01-Feb-2021 06:43 | N15: 07-Feb-2022 15:18 | O15: 31-Jan-2023 20:37
A16: Original Announcement Date | C16: 10-Apr-2018 03:48 | D16: 27-Apr-2018 05:00 | E16: 21-Jan-2019 11:01 | F16: 22-Jan-2020 14:59 | G16: 01-Feb-2021 06:43 | H16: 07-Feb-2022 15:18 | I16: 31-Jan-2023 20:37 | J16: Complete | K16: Complete | L16: Complete | M16: Complete | N16: Complete | O16: Complete
A17: Complete Statement | C17: Complete | D17: Complete | E17: Complete | F17: Complete | G17: Complete | H17: Complete | I17: Complete | J17: No | K17: No | L17: No | M17: No | N17: No | O17: No
A18: Flash Update | C18: No | D18: No | E18: No | F18: No | G18: No | H18: No | I18: No | J18: Yes | K18: Yes | L18: Yes | M18: Yes | N18: Yes | O18: Yes
... A21: Auditor Opinion | C21: Unqualified with Explanation | D21: Unqualified with Explanation | E21: Unqualified with Explanation | F21: Unqualified | G21: Unqualified | H21: Unqualified | I21: Unqualified | J21: Vietnamese Accounting Standards | K21: Vietnamese Accounting Standards | L21: Vietnamese Accounting Standards | M21: Vietnamese Accounting Standards | N21: Vietnamese Accounting Standards | O21: Vietnamese Accounting Standards
A22: Accounting Standard | C22: Vietnamese Accounting Standards | D22: Vietnamese Accounting Standards | E22: Vietnamese Accounting Standards | F22: Vietnamese Accounting Standards | G22: Vietnamese Accounting Standards | H22: Vietnamese Accounting Standards | I22: Vietnamese Accounting Standards
A23: Revenue | C23: 10853155 | D23: 13146515 | E23: 15298335 | F23: 16633960 | G23: 14661417 | H23: 22494961 | I23: 30165801 | J23: ='Revenue breakdown'!G3 -> 38384189 | K23: ='Revenue breakdown'!H3 -> 41212985 | L23: ='Revenue breakdown'!I3 -> 44442666 | M23: ='Revenue breakdown'!J3 -> 48159575 | N23: ='Revenue breakdown'!K3 -> 51416923 | O23: ='Revenue breakdown'!L3 -> 55845117
A24: Gross Revenue | C24: 11722218 | D24: 13795036 | E24: 15889646 | F24: 16988957 | G24: 14799953 | H24: 22619505 | I24: 30276711
A25: Sales Returns and Allowances | C25: -869062 | D25: -648521 | E25: -591311 | F25: -354997 | G25: -138536 | H25: -124544 | I25: -110910
A26: Other Revenue, Total | C26: -- | D26: -- | E26: -- | F26: -- | G26: -- | H26: -- | I26: --
A27: Total Revenue | C27: 10853155 | D27: 13146515 | E27: 15298335 | F27: 16633960 | G27: 14661417 | H27: 22494961 | I27: 30165801 | J27: ='Revenue breakdown'!G3 -> 38384189 | K27: ='Revenue breakdown'!H3 -> 41212985 | L27: ='Revenue breakdown'!I3 -> 44442666 | M27: ='Revenue breakdown'!J3 -> 48159575 | N27: ='Revenue breakdown'!K3 -> 51416923 | O27: ='Revenue breakdown'!L3 -> 55845117
A28: Cost of Revenue, Total | C28: 9442776 | D28: 11330255 | E28: 13254725 | F28: 14522903 | G28: 12620415 | H28: 19343448 | I28: 25462623
A29: Cost of Revenue (COGS) | C29: 9442776 | D29: 11330255 | E29: 13254725 | F29: 14522903 | G29: 12620415 | H29: 19343448 | I29: 25462623 | J29: =J30*'Revenue breakdown'!G3 -> 32399675 | K29: =K30*'Revenue breakdown'!H3 -> 35294455 | L29: =L30*'Revenue breakdown'!I3 -> 37911923 | M29: =M30*'Revenue breakdown'!J3 -> 41008105 | N29: =N30*'Revenue breakdown'!K3 -> 43695406 | O29: =O30*'Revenue breakdown'!L3 -> 47522666
B30: %/rev | E30: =E29/E27 -> 0.86641618 | F30: =F29/F27 -> 0.87308753 | G30: =G29/G27 -> 0.86079095 | H30: =H29/H27 -> 0.85990138 | I30: =I29/I27 -> 0.84408907 | J30: =I30 -> 0.84408907 | K30: =AVERAGE(F30:J30) -> 0.8563916 | L30: =AVERAGE(G30:K30) -> 0.85305241 | M30: =AVERAGE(H30:L30) -> 0.85150471 | N30: =AVERAGE(I30:M30) -> 0.84982537 | O30: =AVERAGE(J30:N30) -> 0.85097263
E31: =(E29-D29)/D29 -> 0.16985231 | F31: =(F29-E29)/E29 -> 0.095677428 | G31: =(G29-F29)/F29 -> -0.13099915 | H31: =(H29-G29)/G29 -> 0.53271093 | I31: =(I29-H29)/H29 -> 0.31634355
A32: Gross Profit | C32: 1410379 | D32: 1816260 | E32: =E27-E29 -> 2043610 | F32: =F27-F29 -> 2111057 | G32: =G27-G29 -> 2041002 | H32: =H27-H29 -> 3151513 | I32: =I27-I29 -> 4703178 | J32: =J27-J29 -> 5984514.5 | K32: =K27-K29 -> 5918530.9 | L32: =L27-L29 -> 6530742.5 | ... O32: =O27-O29 -> 8322450.7
A33: COGS | E33: 13325966 | F33: 14522902 | G33: 12620414 | H33: 19343448 | I33: 25462623
B34: FPT Shop | E34: =E32*'Revenue breakdown'!B8 -> 1997523.6 | F34: =F32*'Revenue breakdown'!C8 -> 2046232.1 | G34: =G32*'Revenue breakdown'!D8 -> 1875943.2 | H34: =H32*'Revenue breakdown'!E8 -> 2599961.8 | I34: =I32*'Revenue breakdown'!F8 -> 3225614.5 | J34: =J35*'Revenue breakdown'!G6 -> 2789753.8 | K34: =K35*'Revenue breakdown'!H6 -> 2860057.5 | L34: =L35*'Revenue breakdown'!I6 -> 2975297.3 | M34: =M35*'Revenue breakdown'!J6 -> 3085391.3 | N34: =N35*'Revenue breakdown'!K6 -> 3161760.6 | O34: =O35*'Revenue breakdown'!L6 -> 3387524.7
B35: %/rev | E35: =E34/E23 -> 0.13057131 | F35: =F34/F23 -> 0.12301533 | G35: =G34/G23 -> 0.12795102 | H35: =H34/H23 -> 0.11557974 | I35: =I34/I23 -> 0.10692952 | J35: =AVERAGE(E35:I35) -> 0.12080938 | K35: =AVERAGE(F35:J35) -> 0.118857 | L35: =AVERAGE(G35:K35) -> 0.11802533 | M35: =AVERAGE(H35:L35) -> 0.11604019 | N35: =AVERAGE(I35:M35) -> 0.11613228 | O35: =AVERAGE(J35:N35) -> 0.11797284
B36: Long Chau | E36: =E32*'Revenue breakdown'!B15 -> 46086.417 | F36: =F32*'Revenue breakdown'!C15 -> 64824.734 | G36: =G32*'Revenue breakdown'!D15 -> 165775.71 | H36: =H32*'Revenue breakdown'!E15 -> 557198.55 | I36: =I32*'Revenue breakdown'!F15 -> 1496112.2 | J36: =J37*'Revenue breakdown'!G12 -> 283155.17 | K36: =K37*'Revenue breakdown'!H12 -> 370737.33 | L36: =L37*'Revenue breakdown'!I12 -> 483947.05 | M36: =M37*'Revenue breakdown'!J12 -> 602516.49 | N36: =N37*'Revenue breakdown'!K12 -> 691022.78 | O36: =O37*'Revenue breakdown'!L12 -> 660862.26
B37: %/rev | E37: =E36/E23 -> 0.003012512 | F37: =F36/F23 -> 0.0038971318 | G37: =G36/G23 -> 0.011306936 | H37: =H36/H23 -> 0.024769927 | I37: =I36/I23 -> 0.049596303 | J37: =AVERAGE(E37:I37) -> 0.018516562 | K37: =AVERAGE(F37:J37) -> 0.021617372 | L37: =AVERAGE(G37:K37) -> 0.02516142 | M37: =AVERAGE(H37:L37) -> 0.027932317 | N37: =AVERAGE(I37:M37) -> 0.028564795 | O37: =AVERAGE(J37:N37) -> 0.024358493
B38: Gross profit margin | E38: =E32/E27 -> 0.13358382 | F38: =F32/F27 -> 0.12691247 | G38: =G32/G27 -> 0.13920905 | H38: =H32/H27 -> 0.14009862 | I38: =I32/I27 -> 0.15591093 | J38: =J32/J27 -> 0.15591093 | K38: =K32/K27 -> 0.1436084 | L38: =L32/L27 -> 0.14694759 | ... O38: =O32/O27 -> 0.14902737
A39: Selling/General/Admin. Expenses, Total | C39: 1180366 | D39: 1454296 | E39: 1583114 | F39: 1768320 | G39: 1935903 | H39: 2656653 | I39: 4146636 | J39: =J42*J23 -> 4961021.4 | K39: =K42*K23 -> 5309552.6 | L39: =L42*L23 -> 5942836.8 | M39: =M42*M23 -> 6379782 | N39: =N42*N23 -> 6913568.8 | O39: =O42*O23 -> 7577439.6
B40: FPT Shop | E40: =E39*'Revenue breakdown'!B8/E23 -> 0.10114908 | F40: =F39*'Revenue breakdown'!C8/F23 -> 0.10304339 | G40: =G39*'Revenue breakdown'!D8/G23 -> 0.12136233 | H40: =H39*'Revenue breakdown'!E8/H23 -> 0.097431066 | I40: =I39*'Revenue breakdown'!F8/I23 -> 0.094276207 | J40: =AVERAGE(E40:I40) -> 0.10345241 | K40: =AVERAGE(F40:J40) -> 0.10391308 | L40: =AVERAGE(G40:K40) -> 0.10408702 | M40: =AVERAGE(H40:L40) -> 0.10063196 | N40: =AVERAGE(I40:M40) -> 0.10127214 | O40: =AVERAGE(J40:N40) -> 0.10267132
B41: Long Chau | E41: =E39*'Revenue breakdown'!B15/'FPT Digital Retail JSC | Income'!E23 -> 0.0023336888 | F41: =F39*'Revenue breakdown'!C15/'FPT Digital Retail JSC | Income'!F23 -> 0.0032644197 | G41: =G39*'Revenue breakdown'!D15/'FPT Digital Retail JSC | Income'!G23 -> 0.010724699 | H41: =H39*'Revenue breakdown'!E15/'FPT Digital Retail JSC | Income'!H23 -> 0.020880479 | I41: =I39*'Revenue breakdown'!F15/'FPT Digital Retail JSC | Income'!I23 -> 0.043727415 | J41: =AVERAGE(E41:I41)*(100%+'Revenue breakdown'!G17) -> 0.025794067 | K41: =AVERAGE(F41:J41)*(100%+'Revenue breakdown'!H17) -> 0.024918948 | L41: =AVERAGE(G41:K41)*(100%+'Revenue breakdown'!I17) -> 0.029632158 | M41: =AVERAGE(H41:L41)*(100%+'Revenue breakdown'!J17) -> 0.031839767 | N41: =AVERAGE(I41:M41)*(100%+'Revenue breakdown'!K17) -> 0.033188822 | O41: =AVERAGE(J41:N41)*(100%+'Revenue breakdown'!L17) -> 0.033015379
B42: %/rev | E42: =E39/E23 -> 0.10348276 | F42: =F39/F23 -> 0.10630782 | G42: =G39/G23 -> 0.13204065 | H42: =H39/H23 -> 0.11809992 | I42: =I39/I23 -> 0.13746149 | J42: =SUM(J40:J41) -> 0.12924648 | K42: =SUM(K40:K41) -> 0.12883203 | L42: =SUM(L40:L41) -> 0.13371918 | M42: =SUM(M40:M41) -> 0.13247173 | N42: =SUM(N40:N41) -> 0.13446096 | O42: =SUM(O40:O41) -> 0.1356867
E43: =E30+E42 -> 0.96989895 | F43: =F30+F42 -> 0.97939535 | G43: =G30+G42 -> 0.99283159 | H43: =H30+H42 -> 0.9780013 | I43: =I30+I42 -> 0.98155056 | J43: =SUM(J42,J30) -> 0.97333555 | K43: =SUM(K42,K30) -> 0.98522363 | L43: =SUM(L42,L30) -> 0.98677159 | M43: =SUM(M42,M30) -> 0.98397643 | N43: =SUM(N42,N30) -> 0.98428633 | O43: =SUM(O42,O30) -> 0.98665933
...

Sheet App
A1: Income Statement | C1: 2016 | D1: 2017 | E1: 2018 | F1: 2019 | G1: 2020 | H1: 2021 | I1: 2022 | J1: 2023F | K1: 2024F | L1: 2025F | M1: 2026F | N1: 2027F | O1: 2028F
A2: Period End Date | C2: 31-Dec-2016 | D2: 31-Dec-2017 | E2: 31-Dec-2018 | F2: 31-Dec-2019 | G2: 31-Dec-2020 | H2: 31-Dec-2021 | I2: 31-Dec-2022 | J2: 31-Dec-2018 | K2: 31-Dec-2019 | L2: 31-Dec-2019 | M2: 31-Dec-2020 | N2: 31-Dec-2021 | O2: 31-Dec-2022
A3: Period Length | C3: 12 Months | D3: 12 Months | E3: 12 Months | F3: 12 Months | G3: 12 Months | H3: 12 Months | I3: 12 Months | J3: Updated | K3: Updated | L3: Restated | M3: Updated | N3: Updated | O3: Updated
A4: Update Type | C4: Updated | D4: Updated | E4: Updated | F4: Updated | G4: Updated | H4: Updated | I4: Updated | J4: 31-Dec-2018 | K4: 31-Dec-2019 | L4: 31-Dec-2020 | M4: 31-Dec-2020 | N4: 31-Dec-2021 | O4: 31-Dec-2022
A5: Statement Date | C5: 31-Dec-2017 | D5: 31-Dec-2017 | E5: 31-Dec-2018 | F5: 31-Dec-2019 | G5: 31-Dec-2020 | H5: 31-Dec-2021 | I5: 31-Dec-2022 | J5: Thousands | K5: Thousands | L5: Thousands | M5: Thousands | N5: Thousands | O5: Thousands
A6: Reporting Unit | C6: Thousands | D6: Thousands | E6: Thousands | F6: Thousands | G6: Thousands | H6: Thousands | I6: Thousands | J6: 06-Jun-2022 | K6: 06-Jun-2023 | L6: 06-Jun-2023 | M6: 06-Jun-2023 | N6: 06-Jun-2023 | O6: 08-Jun-2023
A7: Update Date | C7: 06-Jun-2023 | D7: 06-Jun-2023 | E7: 06-Jun-2023 | F7: 06-Jun-2023 | G7: 06-Jun-2023 | H7: 06-Jun-2023 | I7: 08-Jun-2023 | J7: Vietnamese Dong | K7: Vietnamese Dong | L7: Vietnamese Dong | M7: Vietnamese Dong | N7: Vietnamese Dong | O7: Vietnamese Dong
A8: Reporting Currency | C8: Vietnamese Dong | D8: Vietnamese Dong | E8: Vietnamese Dong | F8: Vietnamese Dong | G8: Vietnamese Dong | H8: Vietnamese Dong | I8: Vietnamese Dong | J8: ARS | K8: ARS | L8: ARS | M8: ARS | N8: ARS | O8: ARS
A9: Source | C9: ARS | D9: ARS | E9: ARS | F9: ARS | G9: ARS | H9: ARS | I9: ARS | J9: 16-Apr-2019 | K9: 31-Mar-2020 | L9: 31-Mar-2021 | M9: 31-Mar-2021 | N9: 14-Mar-2022 | O9: 27-Mar-2023
A10: Source Date | C10: 27-Apr-2018 | D10: 27-Apr-2018 | E10: 16-Apr-2019 | F10: 31-Mar-2020 | G10: 31-Mar-2021 | H10: 14-Mar-2022 | I10: 27-Mar-2023 | J10: 21-Jan-2019 11:01 | K10: 22-Jan-2020 14:59 | L10: 01-Feb-2021 06:43 | M10: 01-Feb-2021 06:43 | N10: 07-Feb-2022 15:18 | O10: 31-Jan-2023 20:37
A11: Original Announcement Date | C11: 10-Apr-2018 03:48 | D11: 27-Apr-2018 05:00 | E11: 21-Jan-2019 11:01 | F11: 22-Jan-2020 14:59 | G11: 01-Feb-2021 06:43 | H11: 07-Feb-2022 15:18 | I11: 31-Jan-2023 20:37 | J11: Complete | K11: Complete | L11: Complete | M11: Complete | N11: Complete | O11: Complete
A12: Complete Statement | C12: Complete | D12: Complete | E12: Complete | F12: Complete | G12: Complete | H12: Complete | I12: Complete | J12: No | K12: No | L12: No | M12: No | N12: No | O12: No
A13: Flash Update | C13: No | D13: No | E13: No | F13: No | G13: No | H13: No | I13: No | J13: Yes | K13: Yes | L13: Yes | M13: Yes | N13: Yes | O13: Yes
... A16: Auditor Opinion | C16: Unqualified with Explanation | D16: Unqualified with Explanation | E16: Unqualified with Explanation | F16: Unqualified | G16: Unqualified | H16: Unqualified | I16: Unqualified | J16: Vietnamese Accounting Standards | K16: Vietnamese Accounting Standards | L16: Vietnamese Accounting Standards | M16: Vietnamese Accounting Standards | N16: Vietnamese Accounting Standards | O16: Vietnamese Accounting Standards
A17: Accounting Standard | C17: Vietnamese Accounting Standards | D17: Vietnamese Accounting Standards | E17: Vietnamese Accounting Standards | F17: Vietnamese Accounting Standards | G17: Vietnamese Accounting Standards | H17: Vietnamese Accounting Standards | I17: Vietnamese Accounting Standards
A18: Revenue | C18: 10853155 | D18: 13146515 | E18: 15298335 | F18: 16633960 | G18: 14661417 | H18: 22494961 | I18: 30165801 | J18: ='Revenue breakdown'!G3 -> 38384189 | K18: ='Revenue breakdown'!H3 -> 41212985 | L18: ='Revenue breakdown'!I3 -> 44442666 | M18: ='Revenue breakdown'!J3 -> 48159575 | N18: ='Revenue breakdown'!K3 -> 51416923 | O18: ='Revenue breakdown'!L3 -> 55845117
A19: Gross Revenue | C19: 11722218 | D19: 13795036 | E19: 15889646 | F19: 16988957 | G19: 14799953 | H19: 22619505 | I19: 30276711
A20: Sales Returns and Allowances | C20: -869062 | D20: -648521 | E20: -591311 | F20: -354997 | G20: -138536 | H20: -124544 | I20: -110910
A21: Other Revenue, Total | C21: -- | D21: -- | E21: -- | F21: -- | G21: -- | H21: -- | I21: --
A22: Total Revenue | C22: 10853155 | D22: 13146515 | E22: 15298335 | F22: 16633960 | G22: 14661417 | H22: 22494961 | I22: 30165801 | J22: ='Revenue breakdown'!G3 -> 38384189 | K22: ='Revenue breakdown'!H3 -> 41212985 | L22: ='Revenue breakdown'!I3 -> 44442666 | M22: ='Revenue breakdown'!J3 -> 48159575 | N22: ='Revenue breakdown'!K3 -> 51416923 | O22: ='Revenue breakdown'!L3 -> 55845117
A23: Cost of Revenue, Total | C23: 9442776 | D23: 11330255 | E23: 13254725 | F23: 14522903 | G23: 12620415 | H23: 19343448 | I23: 25462623
A24: Cost of Revenue (COGS) | C24: 9442776 | D24: 11330255 | E24: 13254725 | F24: 14522903 | G24: 12620415 | H24: 19343448 | I24: 25462623 | J24: =J25*'Revenue breakdown'!G3 -> 32399675 | K24: =K25*'Revenue breakdown'!H3 -> 35294455 | L24: =L25*'Revenue breakdown'!I3 -> 37911923 | M24: =M25*'Revenue breakdown'!J3 -> 41008105 | N24: =N25*'Revenue breakdown'!K3 -> 43695406 | O24: =O25*'Revenue breakdown'!L3 -> 47522666
B25: %/rev | E25: =E24/E22 -> 0.86641618 | F25: =F24/F22 -> 0.87308753 | G25: =G24/G22 -> 0.86079095 | H25: =H24/H22 -> 0.85990138 | I25: =I24/I22 -> 0.84408907 | J25: =I25 -> 0.84408907 | K25: =AVERAGE(F25:J25) -> 0.8563916 | L25: =AVERAGE(G25:K25) -> 0.85305241 | M25: =AVERAGE(H25:L25) -> 0.85150471 | N25: =AVERAGE(I25:M25) -> 0.84982537 | O25: =AVERAGE(J25:N25) -> 0.85097263
E26: =(E24-D24)/D24 -> 0.16985231 | F26: =(F24-E24)/E24 -> 0.095677428 | G26: =(G24-F24)/F24 -> -0.13099915 | H26: =(H24-G24)/G24 -> 0.53271093 | I26: =(I24-H24)/H24 -> 0.31634355
A27: Gross Profit | C27: 1410379 | D27: 1816260 | E27: =E22-E24 -> 2043610 | F27: =F22-F24 -> 2111057 | G27: =G22-G24 -> 2041002 | H27: =H22-H24 -> 3151513 | I27: =I22-I24 -> 4703178 | J27: =J22-J24 -> 5984514.5 | K27: =K22-K24 -> 5918530.9 | L27: =L22-L24 -> 6530742.5 | ... O27: =O22-O24 -> 8322450.7
A28: COGS | E28: 13325966 | F28: 14522902 | G28: 12620414 | H28: 19343448 | I28: 25462623
B29: FPT Shop | E29: =E27*'Revenue breakdown'!B8 -> 1997523.6 | F29: =F27*'Revenue breakdown'!C8 -> 2046232.1 | G29: =G27*'Revenue breakdown'!D8 -> 1875943.2 | H29: =H27*'Revenue breakdown'!E8 -> 2599961.8 | I29: =I27*'Revenue breakdown'!F8 -> 3225614.5 | J29: =J30*'Revenue breakdown'!G6 -> 2789753.8 | K29: =K30*'Revenue breakdown'!H6 -> 2860057.5 | L29: =L30*'Revenue breakdown'!I6 -> 2975297.3 | M29: =M30*'Revenue breakdown'!J6 -> 3085391.3 | N29: =N30*'Revenue breakdown'!K6 -> 3161760.6 | O29: =O30*'Revenue breakdown'!L6 -> 3387524.7
B30: %/rev | E30: =E29/E18 -> 0.13057131 | F30: =F29/F18 -> 0.12301533 | G30: =G29/G18 -> 0.12795102 | H30: =H29/H18 -> 0.11557974 | I30: =I29/I18 -> 0.10692952 | J30: =AVERAGE(E30:I30) -> 0.12080938 | K30: =AVERAGE(F30:J30) -> 0.118857 | L30: =AVERAGE(G30:K30) -> 0.11802533 | M30: =AVERAGE(H30:L30) -> 0.11604019 | N30: =AVERAGE(I30:M30) -> 0.11613228 | O30: =AVERAGE(J30:N30) -> 0.11797284
B31: Long Chau | E31: =E27*'Revenue breakdown'!B15 -> 46086.417 | F31: =F27*'Revenue breakdown'!C15 -> 64824.734 | G31: =G27*'Revenue breakdown'!D15 -> 165775.71 | H31: =H27*'Revenue breakdown'!E15 -> 557198.55 | I31: =I27*'Revenue breakdown'!F15 -> 1496112.2 | J31: =J32*'Revenue breakdown'!G12 -> 283155.17 | K31: =K32*'Revenue breakdown'!H12 -> 370737.33 | L31: =L32*'Revenue breakdown'!I12 -> 483947.05 | M31: =M32*'Revenue breakdown'!J12 -> 602516.49 | N31: =N32*'Revenue breakdown'!K12 -> 691022.78 | O31: =O32*'Revenue breakdown'!L12 -> 660862.26
B32: %/rev | E32: =E31/E18 -> 0.003012512 | F32: =F31/F18 -> 0.0038971318 | G32: =G31/G18 -> 0.011306936 | H32: =H31/H18 -> 0.024769927 | I32: =I31/I18 -> 0.049596303 | J32: =AVERAGE(E32:I32) -> 0.018516562 | K32: =AVERAGE(F32:J32) -> 0.021617372 | L32: =AVERAGE(G32:K32) -> 0.02516142 | M32: =AVERAGE(H32:L32) -> 0.027932317 | N32: =AVERAGE(I32:M32) -> 0.028564795 | O32: =AVERAGE(J32:N32) -> 0.024358493
B33: Gross profit margin | E33: =E27/E22 -> 0.13358382 | F33: =F27/F22 -> 0.12691247 | G33: =G27/G22 -> 0.13920905 | H33: =H27/H22 -> 0.14009862 | I33: =I27/I22 -> 0.15591093 | J33: =J27/J22 -> 0.15591093 | K33: =K27/K22 -> 0.1436084 | L33: =L27/L22 -> 0.14694759 | ... O33: =O27/O22 -> 0.14902737
A34: Selling/General/Admin. Expenses, Total | C34: 1180366 | D34: 1454296 | E34: 1583114 | F34: 1768320 | G34: 1935903 | H34: 2656653 | I34: 4146636 | J34: =J37*J18 -> 4961021.4 | K34: =K37*K18 -> 5309552.6 | L34: =L37*L18 -> 5942836.8 | M34: =M37*M18 -> 6379782 | N34: =N37*N18 -> 6913568.8 | O34: =O37*O18 -> 7577439.6
B35: FPT Shop | E35: =E34*'Revenue breakdown'!B8/E18 -> 0.10114908 | F35: =F34*'Revenue breakdown'!C8/F18 -> 0.10304339 | G35: =G34*'Revenue breakdown'!D8/G18 -> 0.12136233 | H35: =H34*'Revenue breakdown'!E8/H18 -> 0.097431066 | I35: =I34*'Revenue breakdown'!F8/I18 -> 0.094276207 | J35: =AVERAGE(E35:I35) -> 0.10345241 | K35: =AVERAGE(F35:J35) -> 0.10391308 | L35: =AVERAGE(G35:K35) -> 0.10408702 | M35: =AVERAGE(H35:L35) -> 0.10063196 | N35: =AVERAGE(I35:M35) -> 0.10127214 | O35: =AVERAGE(J35:N35) -> 0.10267132
B36: Long Chau | E36: =E34*'Revenue breakdown'!B15/'FPT Digital Retail JSC | Income'!E23 -> 0.0023336888 | F36: =F34*'Revenue breakdown'!C15/'FPT Digital Retail JSC | Income'!F23 -> 0.0032644197 | G36: =G34*'Revenue breakdown'!D15/'FPT Digital Retail JSC | Income'!G23 -> 0.010724699 | H36: =H34*'Revenue breakdown'!E15/'FPT Digital Retail JSC | Income'!H23 -> 0.020880479 | I36: =I34*'Revenue breakdown'!F15/'FPT Digital Retail JSC | Income'!I23 -> 0.043727415 | J36: =AVERAGE(E36:I36)*(100%+'Revenue breakdown'!G17) -> 0.025794067 | K36: =AVERAGE(F36:J36)*(100%+'Revenue breakdown'!H17) -> 0.024918948 | L36: =AVERAGE(G36:K36)*(100%+'Revenue breakdown'!I17) -> 0.029632158 | M36: =AVERAGE(H36:L36)*(100%+'Revenue breakdown'!J17) -> 0.031839767 | N36: =AVERAGE(I36:M36)*(100%+'Revenue breakdown'!K17) -> 0.033188822 | O36: =AVERAGE(J36:N36)*(100%+'Revenue breakdown'!L17) -> 0.033015379
B37: %/rev | E37: =E34/E18 -> 0.10348276 | F37: =F34/F18 -> 0.10630782 | G37: =G34/G18 -> 0.13204065 | H37: =H34/H18 -> 0.11809992 | I37: =I34/I18 -> 0.13746149 | J37: =SUM(J35:J36) -> 0.12924648 | K37: =SUM(K35:K36) -> 0.12883203 | L37: =SUM(L35:L36) -> 0.13371918 | M37: =SUM(M35:M36) -> 0.13247173 | N37: =SUM(N35:N36) -> 0.13446096 | O37: =SUM(O35:O36) -> 0.1356867
E38: =E25+E37 -> 0.96989895 | F38: =F25+F37 -> 0.97939535 | G38: =G25+G37 -> 0.99283159 | H38: =H25+H37 -> 0.9780013 | I38: =I25+I37 -> 0.98155056 | J38: =SUM(J37,J25) -> 0.97333555 | K38: =SUM(K37,K25) -> 0.98522363 | L38: =SUM(L37,L25) -> 0.98677159 | M38: =SUM(M37,M25) -> 0.98397643 | N38: =SUM(N37,N25) -> 0.98428633 | O38: =SUM(O37,O25) -> 0.98665933
E39: =E34/E27 -> 0.77466542 | F39: =F34/F27 -> 0.83764673 | G39: =G34/G27 -> 0.94850617 | H39: =H34/H27 -> 0.84297701 | I39: =I34/I27 -> 0.88166682 | J39: =J34/J27 -> 0.82897642 | K39: =K34/K27 -> 0.8971065 | L39: =L34/L27 -> 0.90997873 | ... O39: =O34/O27 -> 0.91048178
A40: Selling/General/Administrative Expense | C40: 653541 | D40: 808222 | E40: 935387 | F40: 984520 | G40: 1049295 | H40: 1101041 | I40: 1842001
A41: Labor & Related Expense | C41: 526826 | D41: 646073 | E41: 647727 | F41: 783800 | G41: 886608 | H41: 1365500 | I41: 1957142
A42: Advertising Expense | C42: -- | D42: -- | E42: -- | F42: -- | G42: -- | H42: 190112 | I42: 347493
...

Sheet BS
A1: Balance Sheet | C1: 2016 | D1: 2018 | E1: 2019 | F1: 2020 | G1: 2021 | H1: 2022 | I1: 2023F | J1: 2024F | K1: 2025F | L1: 2026F | M1: 2027F | N1: 2028F
B2: 2016 | C2: 2017 | D2: 2018 | E2: 2019 | F2: 2020 | G2: 2021 | H2: 2022 | I2: 2023F | J2: 2024F | K2: 2025F | L2: 2026F | M2: 2027F | N2: 2028F
A3: Period End Date | B3: 31-Dec-2016 | C3: 31-Dec-2017 | D3: 31-Dec-2018 | E3: 31-Dec-2019 | F3: 31-Dec-2020 | G3: 31-Dec-2021 | H3: 31-Dec-2022 | I3: 31-Dec-2018 | J3: 31-Dec-2019 | K3: 31-Dec-2019 | L3: 31-Dec-2020 | M3: 31-Dec-2021 | N3: 31-Dec-2022
A4: Update Type | B4: Updated | C4: Updated | D4: Updated | E4: Updated | F4: Updated | G4: Updated | H4: Updated | I4: Updated | J4: Updated | K4: Restated | L4: Updated | M4: Updated | N4: Updated
A5: Statement Date | B5: 31-Dec-2017 | C5: 31-Dec-2017 | D5: 31-Dec-2018 | E5: 31-Dec-2019 | F5: 31-Dec-2020 | G5: 31-Dec-2021 | H5: 31-Dec-2022 | I5: 31-Dec-2018 | J5: 31-Dec-2019 | K5: 31-Dec-2020 | L5: 31-Dec-2020 | M5: 31-Dec-2021 | N5: 31-Dec-2022
A6: Reporting Unit | B6: Thousands | C6: Thousands | D6: Thousands | E6: Thousands | F6: Thousands | G6: Thousands | H6: Thousands | I6: Thousands | J6: Thousands | K6: Thousands | L6: Thousands | M6: Thousands | N6: Thousands
A7: Update Date | B7: 06-Jun-2023 | C7: 06-Jun-2023 | D7: 06-Jun-2023 | E7: 06-Jun-2023 | F7: 06-Jun-2023 | G7: 06-Jun-2023 | H7: 08-Jun-2023 | I7: 06-Jun-2022 | J7: 06-Jun-2023 | K7: 06-Jun-2023 | L7: 06-Jun-2023 | M7: 06-Jun-2023 | N7: 08-Jun-2023
A8: Reporting Currency | B8: Vietnamese Dong | C8: Vietnamese Dong | D8: Vietnamese Dong | E8: Vietnamese Dong | F8: Vietnamese Dong | G8: Vietnamese Dong | H8: Vietnamese Dong | I8: Vietnamese Dong | J8: Vietnamese Dong | K8: Vietnamese Dong | L8: Vietnamese Dong | M8: Vietnamese Dong | N8: Vietnamese Dong
A9: Source | B9: ARS | C9: ARS | D9: ARS | E9: ARS | F9: ARS | G9: ARS | H9: ARS | I9: ARS | J9: ARS | K9: ARS | L9: ARS | M9: ARS | N9: ARS
A10: Source Date | B10: 27-Apr-2018 | C10: 27-Apr-2018 | D10: 16-Apr-2019 | E10: 31-Mar-2020 | F10: 31-Mar-2021 | G10: 14-Mar-2022 | H10: 27-Mar-2023 | I10: 16-Apr-2019 | J10: 31-Mar-2020 | K10: 31-Mar-2021 | L10: 31-Mar-2021 | M10: 14-Mar-2022 | N10: 27-Mar-2023
A11: Original Announcement Date | B11: 10-Apr-2018 03:48 | C11: 27-Apr-2018 05:00 | D11: 21-Jan-2019 11:01 | E11: 22-Jan-2020 14:59 | F11: 01-Feb-2021 06:43 | G11: 07-Feb-2022 15:18 | H11: 31-Jan-2023 20:37 | I11: 21-Jan-2019 11:01 | J11: 22-Jan-2020 14:59 | K11: 01-Feb-2021 06:43 | L11: 01-Feb-2021 06:43 | M11: 07-Feb-2022 15:18 | N11: 31-Jan-2023 20:37
A12: Complete Statement | B12: Complete | C12: Complete | D12: Complete | E12: Complete | F12: Complete | G12: Complete | H12: Complete | I12: Complete | J12: Complete | K12: Complete | L12: Complete | M12: Complete | N12: Complete
A13: Flash Update | B13: No | C13: No | D13: No | E13: No | F13: No | G13: No | H13: No | I13: No | J13: No | K13: No | L13: No | M13: No | N13: No
A14: Consolidated | B14: Yes | C14: Yes | D14: Yes | E14: Yes | F14: Yes | G14: Yes | H14: Yes | I14: Yes | J14: Yes | K14: Yes | L14: Yes | M14: Yes | N14: Yes
... A17: Accounting Standard | B17: Vietnamese Accounting Standards | C17: Vietnamese Accounting Standards | D17: Vietnamese Accounting Standards | E17: Vietnamese Accounting Standards | F17: Vietnamese Accounting Standards | G17: Vietnamese Accounting Standards | H17: Vietnamese Accounting Standards | I17: Vietnamese Accounting Standards | J17: Vietnamese Accounting Standards | K17: Vietnamese Accounting Standards | L17: Vietnamese Accounting Standards | M17: Vietnamese Accounting Standards | N17: Vietnamese Accounting Standards
A18: Assets (VND Millions)
A19: Cash and Short Term Investments | B19: 1457807 | C19: 638076 | D19: 952518 | E19: 1364293 | F19: 1489663 | G19: 2925710 | H19: 1864556
A20: Cash | B20: 409709 | C20: 567217 | D20: 855378 | E20: 415979 | F20: 551504 | G20: 679939 | H20: 450488
A21: Cash & Equivalents | B21: 1047798 | C21: 70859 | D21: 93000 | E21: 453671 | F21: 150000 | G21: 425271 | H21: 295068
A22: Short Term Investments | B22: 300 | C22: 0 | D22: 4140 | E22: 494643 | F22: 788159 | G22: 1820500 | H22: 1119000
A23: Accounts Receivable - Trade, Net | B23: 115139 | C23: 294862 | D23: 220039 | E23: 260115 | F23: 114599 | G23: 72977 | H23: 82479 | I23: =I50*'Revenue breakdown'!G3 -> 336364.41 | J23: =J50*'Revenue breakdown'!H3 -> 314829.2 | K23: =K50*'Revenue breakdown'!I3 -> 268405.96 | L23: =L50*'Revenue breakdown'!J3 -> 273737.96 | M23: =M50*'Revenue breakdown'!K3 -> 317342.36 | N23: =N50*'Revenue breakdown'!L3 -> 383069.28
A24: Accounts Receivable - Trade, Gross | B24: 119330 | C24: 305662 | D24: 237824 | E24: 294575 | F24: 172585 | G24: 80725 | H24: 89623
A25: Provision for Doubtful Accounts | B25: -4191 | C25: -10800 | D25: -17785 | E25: -34459 | F25: -57986 | G25: -7749 | H25: -7143
A26: Total Receivables (excl. note receivables) | D26: =D28-D31 -> 997840 | E26: =E28-E31 -> 888087 | F26: =F28-F31 -> 545692 | G26: =G28-G31 -> 477246 | H26: =H28-H31 -> 603715 | I26: =I27*'Revenue breakdown'!G3 -> 1512827.6 | J26: =J27*'Revenue breakdown'!H3 -> 1533930.6 | K26: =K27*'Revenue breakdown'!I3 -> 1654138 | L26: =L27*'Revenue breakdown'!J3 -> 1792479.9 | M26: =M27*'Revenue breakdown'!K3 -> 1913717.1 | N26: =N27*'Revenue breakdown'!L3 -> 2078532.6
A27: %rev | D27: =D26/'Revenue breakdown'!B3 -> 0.065225399 | E27: =E26/'Revenue breakdown'!C3 -> 0.053389993 | F27: =F26/'Revenue breakdown'!D3 -> 0.037219595 | G27: =G26/'Revenue breakdown'!E3 -> 0.021215685 | H27: =H26/'Revenue breakdown'!F3 -> 0.020013226 | I27: =AVERAGE(D27:H27) -> 0.039412779 | J27: =MEDIAN(E27:I27) -> 0.037219595 | K27: =MEDIAN(F27:J27) -> 0.037219595 | L27: =MEDIAN(G27:K27) -> 0.037219595 | M27: =MEDIAN(H27:L27) -> 0.037219595 | N27: =MEDIAN(I27:M27) -> 0.037219595
A28: Total Receivables, Net | B28: 852723 | C28: 1026478 | D28: 1118199 | E28: 1210446 | F28: 1430692 | G28: 2037246 | H28: 643715 | I28: =I29*'Revenue breakdown'!G3 -> 2667554.2 | J28: =J29*'Revenue breakdown'!H3 -> 2899346.9 | K28: =K29*'Revenue breakdown'!I3 -> 3105052.5 | L28: =L29*'Revenue breakdown'!J3 -> 3097785.2 | M28: =M29*'Revenue breakdown'!K3 -> 3037460.4 | N28: =N29*'Revenue breakdown'!L3 -> 3720529.4
A29: %rev | D29: =D26/'Revenue breakdown'!B3 -> 0.065225399 | E29: =E28/'Revenue breakdown'!C3 -> 0.072769563 | F29: =F28/'Revenue breakdown'!D3 -> 0.09758211 | G29: =G28/'Revenue breakdown'!E3 -> 0.090564549 | H29: =H28/'Revenue breakdown'!F3 -> 0.021339231 | I29: =AVERAGE(D29:H29) -> 0.06949617 | J29: =AVERAGE(E29:I29) -> 0.070350325 | K29: =AVERAGE(F29:J29) -> 0.069866477 | L29: =AVERAGE(G29:K29) -> 0.06432335 | M29: =AVERAGE(H29:L29) -> 0.059075111 | N29: =AVERAGE(I29:M29) -> 0.066622287
A30: %growth | D30: =D28/C28-1 -> 0.089355057 | E30: =E28/D28-1 -> 0.082496049 | F30: =F28/E28-1 -> 0.18195442 | G30: =G28/F28-1 -> 0.42395848 | H30: =H28/G28-1 -> -0.68402687
A31: Notes Receivable - Short Term | B31: 280150 | C31: 0 | D31: 120359 | E31: 322359 | F31: 885000 | G31: 1560000 | H31: 40000
A32: Receivables - Other | B32: 457434 | C32: 731616 | D32: 777800 | E32: 627971 | F32: 431093 | G32: 404269 | H32: 521235
A33: Total Inventory | B33: 1948265 | C33: 1723478 | D33: 2506219 | E33: 3383542 | F33: 1826718 | G33: 4930359 | H33: 6483828 | I33: =SUM(I36,I39) -> 7819825 | J33: =SUM(J36,J39) -> 8224217.7 | K33: =SUM(K36,K39) -> 8861137.9 | L33: =SUM(L36,L39) -> 9022495.4 | M33: =SUM(M36,M39) -> 9192019.2 | N33: =SUM(N36,N39) -> 9649471.5
A34: growth | E34: =E33/D33-1 -> 0.35005839 | F34: =F33/E33-1 -> -0.46011665 | G34: =G33/F33-1 -> 1.6990258 | H34: =H33/G33-1 -> 0.31508233
A35: weighted | D35: =D33/'Revenue breakdown'!B3 -> 0.16382299 | E35: =E33/'Revenue breakdown'!C3 -> 0.2034117 | F35: =F33/'Revenue breakdown'!D3 -> 0.12459355 | G35: =G33/'Revenue breakdown'!E3 -> 0.21917615 | H35: =H33/'Revenue breakdown'!F3 -> 0.21493969 | I35: =I33/'Revenue breakdown'!G3 -> 0.20372516 | J35: =J33/'Revenue breakdown'!H3 -> 0.19955404 | K35: =K33/'Revenue breakdown'!I3 -> 0.19938358 | ... N35: =N33/'Revenue breakdown'!L3 -> 0.17278989
A36: FPT shop inv | D36: =D33*'Revenue breakdown'!B8 -> 2449700.1 | E36: =E33*'Revenue breakdown'!C8 -> 3279642.6 | F36: =F33*'Revenue breakdown'!D8 -> 1678988.7 | G36: =G33*'Revenue breakdown'!E8 -> 4067489.2 | H36: =H33*'Revenue breakdown'!F8 -> 4446850.5 | I36: =I37*'Revenue breakdown'!G9 -> 5144009.4 | J36: =J37*'Revenue breakdown'!H9 -> 5309698 | K36: =K37*'Revenue breakdown'!I9 -> 5676726 | L36: =L37*'Revenue breakdown'!J9 -> 5801236.4 | M36: =M37*'Revenue breakdown'!K9 -> 6048683.4 | N36: =N37*'Revenue breakdown'!L9 -> 6369454.7
A37: FPT shop inv per store | D37: =D36/'Revenue breakdown'!B9 -> 4596.0602 | E37: =E36/'Revenue breakdown'!C9 -> 5530.5945 | F37: =F36/'Revenue breakdown'!D9 -> 2821.8297 | G37: =G36/'Revenue breakdown'!E9 -> 6286.6912 | H37: =H36/'Revenue breakdown'!F9 -> 5657.5707 | I37: =H37*(1+I38) -> 5949.6767 | J37: =I37*(1+J38) -> 5805.5731 | K37: =J37*(1+K38) -> 5885.1402 | L37: =K37*(1+L38) -> 5854.1987 | M37: =L37*(1+M38) -> 5878.9261 | N37: =M37*(1+N38) -> 5875.8876
A38: growth | E38: =(E37-D37)/D37 -> 0.2033338 | F38: =(F37-E37)/E37 -> -0.48977824 | G38: =(G37-F37)/F37 -> 1.2278776 | H38: =(H37-G37)/G37 -> -0.10007181 | I38: =MEDIAN(E38:H38) -> 0.051630995 | J38: =MEDIAN(F38:I38) -> -0.024220406 | K38: =MEDIAN(G38:J38) -> 0.013705294 | L38: =MEDIAN(H38:K38) -> -0.005257556 | M38: =MEDIAN(I38:L38) -> 0.0042238692 | N38: =MEDIAN(J38:M38) -> -0.0005168434
A39: Long Chau shop inv | D39: =D33*'Revenue breakdown'!B15 -> 56518.932 | E39: =E33*'Revenue breakdown'!C15 -> 103899.24 | F39: =F33*'Revenue breakdown'!D15 -> 148370.98 | G39: =G33*'Revenue breakdown'!E15 -> 871704.76 | H39: =H33*'Revenue breakdown'!F15 -> 2062548.8 | I39: =I40*'Revenue breakdown'!G16 -> 2675815.7 | J39: =J40*'Revenue breakdown'!H16 -> 2914519.7 | K39: =K40*'Revenue breakdown'!I16 -> 3184411.9 | L39: =L40*'Revenue breakdown'!J16 -> 3221259 | M39: =M40*'Revenue breakdown'!K16 -> 3143335.8 | N39: =N40*'Revenue breakdown'!L16 -> 3280016.8
A40: Long Chau inv per store | D40: =D39/'Revenue breakdown'!B16 -> 1883.9644 | E40: =E39/'Revenue breakdown'!C16 -> 1527.9299 | F40: =F39/'Revenue breakdown'!D16 -> 741.85492 | G40: =G39/'Revenue breakdown'!E16 -> 2179.2619 | H40: =H39/'Revenue breakdown'!F16 -> 2062.5488 | I40: =AVERAGE(D40:H40) -> 1679.112 | J40: =I40*(1+J41) -> 1532.3365 | K40: =J40*(1+K41) -> 1424.3307 | L40: =K40*(1+L41) -> 1311.8819 | M40: =L40*(1+M41) -> 1202.7589 | N40: =M40*(1+N41) -> 1105.2579
A41: growth | E41: =(E40-D40)/D40 -> -0.18898152 | F41: =(F40-E40)/E40 -> -0.51447059 | G41: =(G40-F40)/F40 -> 1.937585 | H41: =(H40-G40)/G40 -> -0.053556244 | I41: =MEDIAN(E41:H41) -> -0.12126888 | J41: =MEDIAN(F41:I41) -> -0.087412563 | K41: =MEDIAN(G41:J41) -> -0.070484404 | L41: =MEDIAN(H41:K41) -> -0.078948484 | M41: =MEDIAN(I41:L41) -> -0.083180523 | N41: =MEDIAN(J41:M41) -> -0.081064504
A42: Inventories - Finished Goods | B42: 1909828 | C42: 1679782 | D42: 2507175 | E42: 3380942 | F42: 1847193 | G42: 4933953 | H42: 6487575
...

Sheet Exhibit 
A1: Exhibit | B1: FA summary
B2: SUMMARY OF FINANCIALS | Q2: Exhibit | R2: Inventory
B3: mil VND | C3: 2020A | D3: 2021A | E3: 2022A | F3: 2023F | G3: 2024F | H3: 2025F | I3: 2026F | J3: 2027F
B4: Revenue | C4: ='Revenue breakdown'!D3 -> 14661417 | D4: ='Revenue breakdown'!E3 -> 22494961 | E4: ='Revenue breakdown'!F3 -> 30165801 | F4: ='Revenue breakdown'!G3 -> 38384189 | G4: ='Revenue breakdown'!H3 -> 41212985 | H4: ='Revenue breakdown'!I3 -> 44442666 | I4: ='Revenue breakdown'!J3 -> 48159575 | J4: ='Revenue breakdown'!K3 -> 51416923
B5: Net income | C5: ='FPT Digital Retail JSC | Income'!G89 -> 24719 | D5: ='FPT Digital Retail JSC | Income'!H89 -> 443732 | E5: ='FPT Digital Retail JSC | Income'!I89 -> 390361 | F5: ='FPT Digital Retail JSC | Income'!J89 -> 536537.71 | G5: ='FPT Digital Retail JSC | Income'!K89 -> 541060.85 | H5: ='FPT Digital Retail JSC | Income'!L89 -> 589088.45 | I5: ='FPT Digital Retail JSC | Income'!M89 -> 762226.14 | J5: ='FPT Digital Retail JSC | Income'!N89 -> 758963
B6: EBIT | C6: ='FPT Digital Retail JSC | Income'!G63 -> 14319 | D6: ='FPT Digital Retail JSC | Income'!H63 -> 546196 | E6: ='FPT Digital Retail JSC | Income'!I63 -> 473968 | F6: ='FPT Digital Retail JSC | Income'!J63 -> 642551.35 | G6: ='FPT Digital Retail JSC | Income'!K63 -> 610868.14 | H6: ='FPT Digital Retail JSC | Income'!L63 -> 644701.16 | I6: ='FPT Digital Retail JSC | Income'!M63 -> 828937 | J6: ='FPT Digital Retail JSC | Income'!N63 -> 812315.18
B7: Net margin | C7: ='FPT Digital Retail JSC | Income'!G94 -> 0.0016859898 | D7: ='FPT Digital Retail JSC | Income'!H94 -> 0.01972584 | E7: ='FPT Digital Retail JSC | Income'!I94 -> 0.012940515 | F7: ='FPT Digital Retail JSC | Income'!J94 -> 0.013978091 | G7: ='FPT Digital Retail JSC | Income'!K94 -> 0.013128407 | H7: ='FPT Digital Retail JSC | Income'!L94 -> 0.013255021 | I7: ='FPT Digital Retail JSC | Income'!M94 -> 0.015827094 | J7: ='FPT Digital Retail JSC | Income'!N94 -> 0.014760957
B8: Inventory Turnover | C8: ='Key financial ratios'!G48 -> 4.8 | D8: ='Key financial ratios'!H48 -> 5.7 | E8: ='Key financial ratios'!I48 -> 4.5 | F8: ='FPT Digital Retail JSC | Income'!J29/'FPT Digital Retail JSC | BS'!I37 -> 4.1432736 | G8: ='FPT Digital Retail JSC | Income'!K29/'FPT Digital Retail JSC | BS'!J37 -> 4.2915273 | H8: ='FPT Digital Retail JSC | Income'!L29/'FPT Digital Retail JSC | BS'!K37 -> 4.2784486 | I8: ='FPT Digital Retail JSC | Income'!M29/'FPT Digital Retail JSC | BS'!L37 -> 4.5450957 | J8: ='FPT Digital Retail JSC | Income'!N29/'FPT Digital Retail JSC | BS'!M37 -> 4.7536243
B9: Debt-to-equity | C9: ='Key financial ratios'!G41 -> 2.0481954 | D9: ='Key financial ratios'!H41 -> 3.6381764 | E9: ='Key financial ratios'!I41 -> 2.6706743
A11: Exhibit | B11: Market snapshot
B12: Market Snapshot
B13: Date | C13: Dec 8th, 2023
B14: Closing Price | C14: 101,800 VND
B15: Market cap | C15: 137,743bn VND
